Workbook

Sheet 模板
A1: 统计月 | B1: X | C1: 存量贡献 | D1: 增收分解 | E1: 增收分解 | F1: 增收分解 | G1: 增收分解 | H1: 增收分解 | I1: 客保率 | J1: 客保率 | K1: 客保率 | L1: 收保率 | M1: 收保率 | N1: 收保率 | O1: 价值 | P1: 收入影响因素 | Q1: 收入影响因素 | R1: 收入影响因素 | S1: 收入影响因素 | T1: 收入影响因素 | U1: 收入影响因素 | V1: 收入影响因素 | W1: 产品收保 | X1: 产品收保 | Y1: 产品收保 | Z1: 产品收保 | AA1: 产品收保 | AB1: 产品收保 | AC1: 用户保有 | AD1: 用户保有 | AE1: 用户保有 | AF1: 产品收保 | AG1: 产品收保 | AH1: 产品收保 | AI1: 用户保有 | AJ1: 用户保有 | AK1: 用户保有 | AL1: 产品收保 | AM1: 产品收保 | AN1: 产品收保 | AO1: 用户保有 | AP1: 用户保有 | AQ1: 用户保有 | AR1: 产品收保 | AS1: 产品收保 | AT1: 产品收保 | AU1: 用户保有 | AV1: 用户保有 | AW1: 用户保有 | AX1: 产品收保 | AY1: 产品收保 | AZ1: 产品收保 | BA1: 产品收保 | BB1: 产品收保 | BC1: 产品收保 | BD1: 用户保有 | BE1: 用户保有 | BF1: 用户保有 | BG1: 产品收保 | BH1: 产品收保 | BI1: 产品收保 | BJ1: 用户保有 | BK1: 用户保有 | BL1: 用户保有 | BM1: 产品收保 | BN1: 产品收保 | BO1: 产品收保
A2: ="2026年"&B1&"月" -> 2026年X月 | C2: 存量增收 (万元) | D2: 政企提值客户增收(万元) | E2: 政企降值客户损收(万元) | F2: 政企离网客户损收(万元) | G2: 正波动客户累计变动(万元) | H2: 负波动客户累计变动(万元) | I2: 政企客保率(%) | J2: 环比上月 (PP) | K2: 同比去年 (PP) | L2: 政企客户 收保率(%) | M2: 环比上月 (PP) | N2: 同比去年 (PP) | O2: 政企月均收入增幅(%) | P2: 政企留存客户拉动(pp) | Q2: 政企提值客户拉动(pp) | R2: 政企降值客户拉动(pp) | S2: 政企离网客户拉动(pp) | T2: 政企基本面收入拉动(pp) | U2: 政企双线收入拉动(pp) | V2: 政企其他收入拉动(pp) | W2: 基本面 收保率(%) | X2: 环比上月 (PP) | Y2: 同比去年 (PP) | Z2: 移动收入保有率(%) | AA2: 环比上月 (PP) | AB2: 同比去年 (PP) | AC2: 移动用户保有率(%) | AD2: 环比上月 (PP) | AE2: 同比去年 (PP) | AF2: 宽带收入保有率(%) | AG2: 环比上月 (PP) | AH2: 同比去年 (PP) | AI2: 宽带用户保有率(%) | AJ2: 环比上月 (PP) | AK2: 同比去年 (PP) | AL2: itv收入保有率(%) | AM2: 环比上月 (PP) | AN2: 同比去年 (PP) | AO2: itv用户保有率(%) | AP2: 环比上月 (PP) | AQ2: 同比去年 (PP) | AR2: 固话收入保有率(%) | AS2: 环比上月 (PP) | AT2: 同比去年 (PP) | AU2: 固话用户保有率(%) | AV2: 环比上月 (PP) | AW2: 同比去年 (PP) | AX2: 双线 收保率(%) | AY2: 环比上月 (PP) | AZ2: 同比去年 (PP) | BA2: 互联网专线收入保有率(%) | BB2: 环比上月 (PP) | BC2: 同比去年 (PP) | BD2: 互联网专线用户保有率(%) | BE2: 环比上月 (PP) | BF2: 同比去年 (PP) | BG2: 组网专线收入保有率(%) | BH2: 环比上月 (PP) | BI2: 同比去年 (PP) | BJ2: 组网专线用户保有率(%) | BK2: 环比上月 (PP) | BL2: 同比去年 (PP) | BM2: 其他用户 收保率(%) | BN2: 环比上月 (PP) | BO2: 同比去年 (PP)
B3: 全省 | C3: =ROUND(VLOOKUP(B3,拍照客户_客户级!$A$2:$BX$27,28,FALSE)/10000,3) -> 1296.436 | D3: =ROUND(VLOOKUP(B3,拍照客户_客户级!$A$2:$BX$27,29,FALSE)/10000,3) -> 82784.449 | E3: =ROUND(VLOOKUP(B3,拍照客户_客户级!$A$2:$BX$27,30,FALSE)/10000,3) -> -78769.286 | F3: =ROUND(VLOOKUP(B3,拍照客户_客户级!$A$2:$BX$27,33,FALSE)/10000,3) -> -7238.194 | G3: =ROUND(VLOOKUP(B3,拍照客户_客户级!$A$2:$BX$27,31,FALSE)/10000,3) -> 4629.164 | H3: =ROUND(VLOOKUP(B3,拍照客户_客户级!$A$2:$BX$27,32,FALSE)/10000,3) -> -109.697 | I3: =VLOOKUP(B3,拍照客户_客户级!$A$2:$BX$27,13,FALSE) -> 92.861774 | J3: =VLOOKUP(B3,拍照客户_客户级!$A$2:$BX$27,15,FALSE) -> -1.0560788 | K3: =VLOOKUP(B3,拍照客户_客户级!$A$2:$BX$27,14,FALSE) -> 0.63296797 | L3: =VLOOKUP(B3,拍照客户_客户级!$A$2:$BX$27,34,FALSE) -> 100.15162 | M3: =VLOOKUP(B3,拍照客户_客户级!$A$2:$BX$27,36,FALSE) -> -0.67135429 | N3: =VLOOKUP(B3,拍照客户_客户级!$A$2:$BX$27,35,FALSE) -> -0.55947453 | O3: =VLOOKUP(B3,拍照客户_客户级!$A$2:$BX$27,49,FALSE) -> -1.3037645 | P3: =VLOOKUP(B3,拍照客户_客户级!$A$2:$BX$27,50,FALSE) -> -0.25489643 | Q3: =VLOOKUP(B3,拍照客户_客户级!$A$2:$BX$27,51,FALSE) -> 9.3839383 | R3: =VLOOKUP(B3,拍照客户_客户级!$A$2:$BX$27,52,FALSE) -> -9.6860932 | S3: =VLOOKUP(B3,拍照客户_客户级!$A$2:$BX$27,55,FALSE) -> -1.048868 | T3: =VLOOKUP(B3,拍照客户_业务级!$A$9:$KF$30,282,FALSE) -> -0.74309274 | U3: =VLOOKUP(B3,拍照客户_业务级!$A$9:$KF$30,284,FALSE) -> -0.045142861 | V3: =VLOOKUP(B3,拍照客户_业务级!$A$9:$KF$30,285,FALSE) -> -2.0302537 | W3: =VLOOKUP(B3,拍照客户_业务级!$A$9:$KF$30,251,FALSE) -> 100.38643 | X3: =VLOOKUP(B3,拍照客户_业务级!$A$9:$KF$30,253,FALSE) -> -0.44767892 | Y3: =VLOOKUP(B3,拍照客户_业务级!$A$9:$KF$30,252,FALSE) -> 0.2942875 | Z3: =VLOOKUP(B3,拍照客户_业务级!$A$9:$KF$30,204,FALSE) -> 102.84551 | AA3: =VLOOKUP(B3,拍照客户_业务级!$A$9:$KF$30,206,FALSE) -> -0.21363964 | AB3: =VLOOKUP(B3,拍照客户_业务级!$A$9:$KF$30,205,FALSE) -> 0.31079069 | AC3: =VLOOKUP(B3,拍照客户_业务级!$A$9:$KF$30,78,FALSE) -> 94.805045 | AD3: =VLOOKUP(B3,拍照客户_业务级!$A$9:$KF$30,80,FALSE) -> -0.77929684 | AE3: =VLOOKUP(B3,拍照客户_业务级!$A$9:$KF$30,79,FALSE) -> -0.66548664 | AF3: =VLOOKUP(B3,拍照客户_业务级!$A$9:$KF$30,213,FALSE) -> 101.61575 | AG3: =VLOOKUP(B3,拍照客户_业务级!$A$9:$KF$30,215,FALSE) -> -0.80964738 | AH3: =VLOOKUP(B3,拍照客户_业务级!$A$9:$KF$30,214,FALSE) -> 1.6220152 | AI3: =VLOOKUP(B3,拍照客户_业务级!$A$9:$KF$30,94,FALSE) -> 96.459398 | AJ3: =VLOOKUP(B3,拍照客户_业务级!$A$9:$KF$30,96,FALSE) -> 0.98093672 | AK3: =VLOOKUP(B3,拍照客户_业务级!$A$9:$KF$30,95,FALSE) -> 2.190225 | AL3: =VLOOKUP(B3,拍照客户_业务级!$A$9:$KF$30,221,FALSE) -> 97.09008 | AM3: =VLOOKUP(B3,拍照客户_业务级!$A$9:$KF$30,223,FALSE) -> -1.0184942 | AN3: =VLOOKUP(B3,拍照客户_业务级!$A$9:$KF$30,222,FALSE) -> -1.1796262 | AO3: =VLOOKUP(B3,拍照客户_业务级!$A$9:$KF$30,108,FALSE) -> 89.752201 | AP3: =VLOOKUP(B3,拍照客户_业务级!$A$9:$KF$30,110,FALSE) -> -2.2865494 | AQ3: =VLOOKUP(B3,拍照客户_业务级!$A$9:$KF$30,109,FALSE) -> -5.6512157 | AR3: =VLOOKUP(B3,拍照客户_业务级!$A$9:$KF$30,227,FALSE) -> 93.328954 | AS3: =VLOOKUP(B3,拍照客户_业务级!$A$9:$KF$30,229,FALSE) -> -0.72092943 | AT3: =VLOOKUP(B3,拍照客户_业务级!$A$9:$KF$30,228,FALSE) -> -1.070064 | AU3: =VLOOKUP(B3,拍照客户_业务级!$A$9:$KF$30,118,FALSE) -> 95.599814 | AV3: =VLOOKUP(B3,拍照客户_业务级!$A$9:$KF$30,120,FALSE) -> -0.4692432 | AW3: =VLOOKUP(B3,拍照客户_业务级!$A$9:$KF$30,119,FALSE) -> 0.36737009 | AX3: =VLOOKUP(B3,拍照客户_业务级!$A$9:$KF$30,254,FALSE) -> 100.16258 | AY3: =VLOOKUP(B3,拍照客户_业务级!$A$9:$KF$30,256,FALSE) -> -0.5880241 | AZ3: =VLOOKUP(B3,拍照客户_业务级!$A$9:$KF$30,255,FALSE) -> -0.35521745 | BA3: =VLOOKUP(B3,拍照客户_业务级!$A$9:$KF$30,233,FALSE) -> 100.23911 | BB3: =VLOOKUP(B3,拍照客户_业务级!$A$9:$KF$30,235,FALSE) -> -0.49811357 | BC3: =VLOOKUP(B3,拍照客户_业务级!$A$9:$KF$30,234,FALSE) -> -0.33352607 | BD3: =VLOOKUP(B3,拍照客户_业务级!$A$9:$KF$30,123,FALSE) -> 99.716812 | BE3: =VLOOKUP(B3,拍照客户_业务级!$A$9:$KF$30,125,FALSE) -> -0.24974921 | BF3: =VLOOKUP(B3,拍照客户_业务级!$A$9:$KF$30,124,FALSE) -> 1.3411897 | BG3: =VLOOKUP(B3,拍照客户_业务级!$A$9:$KF$30,239,FALSE) -> 100.09062 | BH3: =VLOOKUP(B3,拍照客户_业务级!$A$9:$KF$30,241,FALSE) -> -0.67255453 | BI3: =VLOOKUP(B3,拍照客户_业务级!$A$9:$KF$30,240,FALSE) -> -0.37439301 | BJ3: =VLOOKUP(B3,拍照客户_业务级!$A$9:$KF$30,128,FALSE) -> 94.725349 | BK3: =VLOOKUP(B3,拍照客户_业务级!$A$9:$KF$30,130,FALSE) -> -0.68061926 | BL3: =VLOOKUP(B3,拍照客户_业务级!$A$9:$KF$30,129,FALSE) -> -5.7543031 | BM3: =VLOOKUP(B3,拍照客户_业务级!$A$9:$KF$30,245,FALSE) -> 99.19101 | BN3: =VLOOKUP(B3,拍照客户_业务级!$A$9:$KF$30,247,FALSE) -> -1.8373781 | BO3: =VLOOKUP(B3,拍照客户_业务级!$A$9:$KF$30,246,FALSE) -> -5.2269483
A4: 珠一 | B4: 深圳 | C4: =ROUND(VLOOKUP(B4,拍照客户_客户级!$A$2:$BX$27,28,FALSE)/10000,3) -> 931.008 | D4: =ROUND(VLOOKUP(B4,拍照客户_客户级!$A$2:$BX$27,29,FALSE)/10000,3) -> 18434.393 | E4: =ROUND(VLOOKUP(B4,拍照客户_客户级!$A$2:$BX$27,30,FALSE)/10000,3) -> -16563.335 | F4: =ROUND(VLOOKUP(B4,拍照客户_客户级!$A$2:$BX$27,33,FALSE)/10000,3) -> -1241.586 | G4: =ROUND(VLOOKUP(B4,拍照客户_客户级!$A$2:$BX$27,31,FALSE)/10000,3) -> 403.802 | H4: =ROUND(VLOOKUP(B4,拍照客户_客户级!$A$2:$BX$27,32,FALSE)/10000,3) -> -102.265 | I4: =VLOOKUP(B4,拍照客户_客户级!$A$2:$BX$27,13,FALSE) -> 94.506551 | J4: =VLOOKUP(B4,拍照客户_客户级!$A$2:$BX$27,15,FALSE) -> -0.69784847 | K4: =VLOOKUP(B4,拍照客户_客户级!$A$2:$BX$27,14,FALSE) -> -0.043089371 | L4: =VLOOKUP(B4,拍照客户_客户级!$A$2:$BX$27,34,FALSE) -> 100.37193 | M4: =VLOOKUP(B4,拍照客户_客户级!$A$2:$BX$27,36,FALSE) -> -0.31604073 | N4: =VLOOKUP(B4,拍照客户_客户级!$A$2:$BX$27,35,FALSE) -> 0.082130995 | O4: =VLOOKUP(B4,拍照客户_客户级!$A$2:$BX$27,49,FALSE) -> -0.64409339 | P4: =VLOOKUP(B4,拍照客户_客户级!$A$2:$BX$27,50,FALSE) -> 0.013747505 | Q4: =VLOOKUP(B4,拍照客户_客户级!$A$2:$BX$27,51,FALSE) -> 7.1766816 | R4: =VLOOKUP(B4,拍照客户_客户级!$A$2:$BX$27,52,FALSE) -> -7.1801231 | S4: =VLOOKUP(B4,拍照客户_客户级!$A$2:$BX$27,55,FALSE) -> -0.65784089 | T4: =VLOOKUP(B4,拍照客户_业务级!$A$9:$KF$30,282,FALSE) -> -0.46594344 | U4: =VLOOKUP(B4,拍照客户_业务级!$A$9:$KF$30,284,FALSE) -> 1.2517161 | V4: =VLOOKUP(B4,拍照客户_业务级!$A$9:$KF$30,285,FALSE) -> -2.9735278 | W4: =VLOOKUP(B4,拍照客户_业务级!$A$9:$KF$30,251,FALSE) -> 99.477575 | X4: =VLOOKUP(B4,拍照客户_业务级!$A$9:$KF$30,253,FALSE) -> -0.28296128 | Y4: =VLOOKUP(B4,拍照客户_业务级!$A$9:$KF$30,252,FALSE) -> 0.24137363 | Z4: =VLOOKUP(B4,拍照客户_业务级!$A$9:$KF$30,204,FALSE) -> 101.73022 | AA4: =VLOOKUP(B4,拍照客户_业务级!$A$9:$KF$30,206,FALSE) -> -0.11543364 | AB4: =VLOOKUP(B4,拍照客户_业务级!$A$9:$KF$30,205,FALSE) -> 0.86020661 | AC4: =VLOOKUP(B4,拍照客户_业务级!$A$9:$KF$30,78,FALSE) -> 96.181634 | AD4: =VLOOKUP(B4,拍照客户_业务级!$A$9:$KF$30,80,FALSE) -> -0.62101696 | AE4: =VLOOKUP(B4,拍照客户_业务级!$A$9:$KF$30,79,FALSE) -> -0.12768032 | AF4: =VLOOKUP(B4,拍照客户_业务级!$A$9:$KF$30,213,FALSE) -> 100.24591 | AG4: =VLOOKUP(B4,拍照客户_业务级!$A$9:$KF$30,215,FALSE) -> -0.66460558 | AH4: =VLOOKUP(B4,拍照客户_业务级!$A$9:$KF$30,214,FALSE) -> 1.4729424 | AI4: =VLOOKUP(B4,拍照客户_业务级!$A$9:$KF$30,94,FALSE) -> 95.01038 | AJ4: =VLOOKUP(B4,拍照客户_业务级!$A$9:$KF$30,96,FALSE) -> -0.85954191 | AK4: =VLOOKUP(B4,拍照客户_业务级!$A$9:$KF$30,95,FALSE) -> 4.0523405 | AL4: =VLOOKUP(B4,拍照客户_业务级!$A$9:$KF$30,221,FALSE) -> 95.849967 | AM4: =VLOOKUP(B4,拍照客户_业务级!$A$9:$KF$30,223,FALSE) -> -0.60042794 | AN4: =VLOOKUP(B4,拍照客户_业务级!$A$9:$KF$30,222,FALSE) -> -3.8239988 | AO4: =VLOOKUP(B4,拍照客户_业务级!$A$9:$KF$30,108,FALSE) -> 85.492981 | AP4: =VLOOKUP(B4,拍照客户_业务级!$A$9:$KF$30,110,FALSE) -> -3.5951617 | AQ4: =VLOOKUP(B4,拍照客户_业务级!$A$9:$KF$30,109,FALSE) -> -7.478916 | AR4: =VLOOKUP(B4,拍照客户_业务级!$A$9:$KF$30,227,FALSE) -> 93.504069 | AS4: =VLOOKUP(B4,拍照客户_业务级!$A$9:$KF$30,229,FALSE) -> -0.40758891 | AT4: =VLOOKUP(B4,拍照客户_业务级!$A$9:$KF$30,228,FALSE) -> -2.2044326 | AU4: =VLOOKUP(B4,拍照客户_业务级!$A$9:$KF$30,118,FALSE) -> 93.961591 | AV4: =VLOOKUP(B4,拍照客户_业务级!$A$9:$KF$30,120,FALSE) -> -0.73580133 | AW4: =VLOOKUP(B4,拍照客户_业务级!$A$9:$KF$30,119,FALSE) -> 0.045044129 | AX4: =VLOOKUP(B4,拍照客户_业务级!$A$9:$KF$30,254,FALSE) -> 102.80192 | AY4: =VLOOKUP(B4,拍照客户_业务级!$A$9:$KF$30,256,FALSE) -> 0.020740471 | AZ4: =VLOOKUP(B4,拍照客户_业务级!$A$9:$KF$30,255,FALSE) -> 2.6097277 | BA4: =VLOOKUP(B4,拍照客户_业务级!$A$9:$KF$30,233,FALSE) -> 100.70614 | BB4: =VLOOKUP(B4,拍照客户_业务级!$A$9:$KF$30,235,FALSE) -> -0.34194066 | BC4: =VLOOKUP(B4,拍照客户_业务级!$A$9:$KF$30,234,FALSE) -> -0.22605011 | BD4: =VLOOKUP(B4,拍照客户_业务级!$A$9:$KF$30,123,FALSE) -> 98.667568 | BE4: =VLOOKUP(B4,拍照客户_业务级!$A$9:$KF$30,125,FALSE) -> -0.97035821 | BF4: =VLOOKUP(B4,拍照客户_业务级!$A$9:$KF$30,124,FALSE) -> 0.44374998 | BG4: =VLOOKUP(B4,拍照客户_业务级!$A$9:$KF$30,239,FALSE) -> 104.58297 | BH4: =VLOOKUP(B4,拍照客户_业务级!$A$9:$KF$30,241,FALSE) -> 0.32895698 | BI4: =VLOOKUP(B4,拍照客户_业务级!$A$9:$KF$30,240,FALSE) -> 4.9945974 | BJ4: =VLOOKUP(B4,拍照客户_业务级!$A$9:$KF$30,128,FALSE) -> 96.982707 | BK4: =VLOOKUP(B4,拍照客户_业务级!$A$9:$KF$30,130,FALSE) -> 2.9730441 | BL4: =VLOOKUP(B4,拍照客户_业务级!$A$9:$KF$30,129,FALSE) -> -2.590929 | BM4: =VLOOKUP(B4,拍照客户_业务级!$A$9:$KF$30,245,FALSE) -> 93.255075 | BN4: =VLOOKUP(B4,拍照客户_业务级!$A$9:$KF$30,247,FALSE) -> -1.7586458 | BO4: =VLOOKUP(B4,拍照客户_业务级!$A$9:$KF$30,246,FALSE) -> -11.267264
B5: 广州 | C5: =ROUND(VLOOKUP(B5,拍照客户_客户级!$A$2:$BX$27,28,FALSE)/10000,3) -> 1297.745 | D5: =ROUND(VLOOKUP(B5,拍照客户_客户级!$A$2:$BX$27,29,FALSE)/10000,3) -> 24344.562 | E5: =ROUND(VLOOKUP(B5,拍照客户_客户级!$A$2:$BX$27,30,FALSE)/10000,3) -> -23016.358 | F5: =ROUND(VLOOKUP(B5,拍照客户_客户级!$A$2:$BX$27,33,FALSE)/10000,3) -> -2099.214 | G5: =ROUND(VLOOKUP(B5,拍照客户_客户级!$A$2:$BX$27,31,FALSE)/10000,3) -> 1798.067 | H5: =ROUND(VLOOKUP(B5,拍照客户_客户级!$A$2:$BX$27,32,FALSE)/10000,3) -> 270.689 | I5: =VLOOKUP(B5,拍照客户_客户级!$A$2:$BX$27,13,FALSE) -> 92.325435 | J5: =VLOOKUP(B5,拍照客户_客户级!$A$2:$BX$27,15,FALSE) -> -1.4025169 | K5: =VLOOKUP(B5,拍照客户_客户级!$A$2:$BX$27,14,FALSE) -> 1.4840819 | L5: =VLOOKUP(B5,拍照客户_客户级!$A$2:$BX$27,34,FALSE) -> 100.62068 | M5: =VLOOKUP(B5,拍照客户_客户级!$A$2:$BX$27,36,FALSE) -> -1.2085782 | N5: =VLOOKUP(B5,拍照客户_客户级!$A$2:$BX$27,35,FALSE) -> -1.3583069 | O5: =VLOOKUP(B5,拍照客户_客户级!$A$2:$BX$27,49,FALSE) -> -1.4882617 | P5: =VLOOKUP(B5,拍照客户_客户级!$A$2:$BX$27,50,FALSE) -> -0.17955065 | Q5: =VLOOKUP(B5,拍照客户_客户级!$A$2:$BX$27,51,FALSE) -> 11.124727 | R5: =VLOOKUP(B5,拍照客户_客户级!$A$2:$BX$27,52,FALSE) -> -11.354277 | S5: =VLOOKUP(B5,拍照客户_客户级!$A$2:$BX$27,55,FALSE) -> -1.3087111 | T5: =VLOOKUP(B5,拍照客户_业务级!$A$9:$KF$30,282,FALSE) -> -1.0078805 | U5: =VLOOKUP(B5,拍照客户_业务级!$A$9:$KF$30,284,FALSE) -> -1.0391915 | V5: =VLOOKUP(B5,拍照客户_业务级!$A$9:$KF$30,285,FALSE) -> -3.0916862 | W5: =VLOOKUP(B5,拍照客户_业务级!$A$9:$KF$30,251,FALSE) -> 101.38763 | X5: =VLOOKUP(B5,拍照客户_业务级!$A$9:$KF$30,253,FALSE) -> -0.67548592 | Y5: =VLOOKUP(B5,拍照客户_业务级!$A$9:$KF$30,252,FALSE) -> 0.35436556 | Z5: =VLOOKUP(B5,拍照客户_业务级!$A$9:$KF$30,204,FALSE) -> 105.08926 | AA5: =VLOOKUP(B5,拍照客户_业务级!$A$9:$KF$30,206,FALSE) -> -0.37898586 | AB5: =VLOOKUP(B5,拍照客户_业务级!$A$9:$KF$30,205,FALSE) -> 1.1841056 | AC5: =VLOOKUP(B5,拍照客户_业务级!$A$9:$KF$30,78,FALSE) -> 93.803065 | AD5: =VLOOKUP(B5,拍照客户_业务级!$A$9:$KF$30,80,FALSE) -> -1.2413091 | AE5: =VLOOKUP(B5,拍照客户_业务级!$A$9:$KF$30,79,FALSE) -> -1.7616818 | AF5: =VLOOKUP(B5,拍照客户_业务级!$A$9:$KF$30,213,FALSE) -> 99.1311 | AG5: =VLOOKUP(B5,拍照客户_业务级!$A$9:$KF$30,215,FALSE) -> -1.7991988 | AH5: =VLOOKUP(B5,拍照客户_业务级!$A$9:$KF$30,214,FALSE) -> -2.1497876 | AI5: =VLOOKUP(B5,拍照客户_业务级!$A$9:$KF$30,94,FALSE) -> 100.09788 | AJ5: =VLOOKUP(B5,拍照客户_业务级!$A$9:$KF$30,96,FALSE) -> 4.2805731 | AK5: =VLOOKUP(B5,拍照客户_业务级!$A$9:$KF$30,95,FALSE) -> 8.3420419 | AL5: =VLOOKUP(B5,拍照客户_业务级!$A$9:$KF$30,221,FALSE) -> 91.065367 | AM5: =VLOOKUP(B5,拍照客户_业务级!$A$9:$KF$30,223,FALSE) -> -3.4451536 | AN5: =VLOOKUP(B5,拍照客户_业务级!$A$9:$KF$30,222,FALSE) -> 15.558223 | AO5: =VLOOKUP(B5,拍照客户_业务级!$A$9:$KF$30,108,FALSE) -> 88.420232 | AP5: =VLOOKUP(B5,拍照客户_业务级!$A$9:$KF$30,110,FALSE) -> -2.3112105 | AQ5: =VLOOKUP(B5,拍照客户_业务级!$A$9:$KF$30,109,FALSE) -> -6.811128 | AR5: =VLOOKUP(B5,拍照客户_业务级!$A$9:$KF$30,227,FALSE) -> 93.188629 | AS5: =VLOOKUP(B5,拍照客户_业务级!$A$9:$KF$30,229,FALSE) -> -0.4846277 | AT5: =VLOOKUP(B5,拍照客户_业务级!$A$9:$KF$30,228,FALSE) -> -1.7376078 | AU5: =VLOOKUP(B5,拍照客户_业务级!$A$9:$KF$30,118,FALSE) -> 96.122787 | AV5: =VLOOKUP(B5,拍照客户_业务级!$A$9:$KF$30,120,FALSE) -> -0.23003065 | AW5: =VLOOKUP(B5,拍照客户_业务级!$A$9:$KF$30,119,FALSE) -> 0.058077145 | AX5: =VLOOKUP(B5,拍照客户_业务级!$A$9:$KF$30,254,FALSE) -> 97.956548 | AY5: =VLOOKUP(B5,拍照客户_业务级!$A$9:$KF$30,256,FALSE) -> -0.90805581 | AZ5: =VLOOKUP(B5,拍照客户_业务级!$A$9:$KF$30,255,FALSE) -> -3.453071 | BA5: =VLOOKUP(B5,拍照客户_业务级!$A$9:$KF$30,233,FALSE) -> 98.005207 | BB5: =VLOOKUP(B5,拍照客户_业务级!$A$9:$KF$30,235,FALSE) -> -0.66985985 | BC5: =VLOOKUP(B5,拍照客户_业务级!$A$9:$KF$30,234,FALSE) -> -2.6030582 | BD5: =VLOOKUP(B5,拍照客户_业务级!$A$9:$KF$30,123,FALSE) -> 96.361647 | BE5: =VLOOKUP(B5,拍照客户_业务级!$A$9:$KF$30,125,FALSE) -> 0.11854283 | BF5: =VLOOKUP(B5,拍照客户_业务级!$A$9:$KF$30,124,FALSE) -> 0.89236202 | BG5: =VLOOKUP(B5,拍照客户_业务级!$A$9:$KF$30,239,FALSE) -> 97.88382 | BH5: =VLOOKUP(B5,拍照客户_业务级!$A$9:$KF$30,241,FALSE) -> -1.2640757 | BI5: =VLOOKUP(B5,拍照客户_业务级!$A$9:$KF$30,240,FALSE) -> -4.8172049 | BJ5: =VLOOKUP(B5,拍照客户_业务级!$A$9:$KF$30,128,FALSE) -> 89.838277 | BK5: =VLOOKUP(B5,拍照客户_业务级!$A$9:$KF$30,130,FALSE) -> -3.2936039 | BL5: =VLOOKUP(B5,拍照客户_业务级!$A$9:$KF$30,129,FALSE) -> -8.7659709 | BM5: =VLOOKUP(B5,拍照客户_业务级!$A$9:$KF$30,245,FALSE) -> 106.20644 | BN5: =VLOOKUP(B5,拍照客户_业务级!$A$9:$KF$30,247,FALSE) -> -3.6041099 | BO5: =VLOOKUP(B5,拍照客户_业务级!$A$9:$KF$30,246,FALSE) -> -1.0219019
B6: 东莞 | C6: =ROUND(VLOOKUP(B6,拍照客户_客户级!$A$2:$BX$27,28,FALSE)/10000,3) -> -1719.588 | D6: =ROUND(VLOOKUP(B6,拍照客户_客户级!$A$2:$BX$27,29,FALSE)/10000,3) -> 4587.97 | E6: =ROUND(VLOOKUP(B6,拍照客户_客户级!$A$2:$BX$27,30,FALSE)/10000,3) -> -5678.345 | F6: =ROUND(VLOOKUP(B6,拍照客户_客户级!$A$2:$BX$27,33,FALSE)/10000,3) -> -819.933 | G6: =ROUND(VLOOKUP(B6,拍照客户_客户级!$A$2:$BX$27,31,FALSE)/10000,3) -> 244.911 | H6: =ROUND(VLOOKUP(B6,拍照客户_客户级!$A$2:$BX$27,32,FALSE)/10000,3) -> -54.19 | I6: =VLOOKUP(B6,拍照客户_客户级!$A$2:$BX$27,13,FALSE) -> 92.218086 | J6: =VLOOKUP(B6,拍照客户_客户级!$A$2:$BX$27,15,FALSE) -> -1.1277089 | K6: =VLOOKUP(B6,拍照客户_客户级!$A$2:$BX$27,14,FALSE) -> -0.10325729 | L6: =VLOOKUP(B6,拍照客户_客户级!$A$2:$BX$27,34,FALSE) -> 97.553055 | M6: =VLOOKUP(B6,拍照客户_客户级!$A$2:$BX$27,36,FALSE) -> -0.26269053 | N6: =VLOOKUP(B6,拍照客户_客户级!$A$2:$BX$27,35,FALSE) -> -2.7136729 | O6: =VLOOKUP(B6,拍照客户_客户级!$A$2:$BX$27,49,FALSE) -> -3.0609371 | P6: =VLOOKUP(B6,拍照客户_客户级!$A$2:$BX$27,50,FALSE) -> -1.8195905 | Q6: =VLOOKUP(B6,拍照客户_客户级!$A$2:$BX$27,51,FALSE) -> 6.4001904 | R6: =VLOOKUP(B6,拍照客户_客户级!$A$2:$BX$27,52,FALSE) -> -8.2443816 | S6: =VLOOKUP(B6,拍照客户_客户级!$A$2:$BX$27,55,FALSE) -> -1.2413466 | T6: =VLOOKUP(B6,拍照客户_业务级!$A$9:$KF$30,282,FALSE) -> -0.72297361 | U6: =VLOOKUP(B6,拍照客户_业务级!$A$9:$KF$30,284,FALSE) -> -1.6898571 | V6: =VLOOKUP(B6,拍照客户_业务级!$A$9:$KF$30,285,FALSE) -> -0.79241395 | W6: =VLOOKUP(B6,拍照客户_业务级!$A$9:$KF$30,251,FALSE) -> 99.54661 | X6: =VLOOKUP(B6,拍照客户_业务级!$A$9:$KF$30,253,FALSE) -> -0.29847813 | Y6: =VLOOKUP(B6,拍照客户_业务级!$A$9:$KF$30,252,FALSE) -> -1.4781732 | Z6: =VLOOKUP(B6,拍照客户_业务级!$A$9:$KF$30,204,FALSE) -> 101.53326 | AA6: =VLOOKUP(B6,拍照客户_业务级!$A$9:$KF$30,206,FALSE) -> -0.1840656 | AB6: =VLOOKUP(B6,拍照客户_业务级!$A$9:$KF$30,205,FALSE) -> -2.1066895 | AC6: =VLOOKUP(B6,拍照客户_业务级!$A$9:$KF$30,78,FALSE) -> 94.655146 | AD6: =VLOOKUP(B6,拍照客户_业务级!$A$9:$KF$30,80,FALSE) -> -0.80972239 | AE6: =VLOOKUP(B6,拍照客户_业务级!$A$9:$KF$30,79,FALSE) -> -1.1818826 | AF6: =VLOOKUP(B6,拍照客户_业务级!$A$9:$KF$30,213,FALSE) -> 100.23317 | AG6: =VLOOKUP(B6,拍照客户_业务级!$A$9:$KF$30,215,FALSE) -> -0.48210266 | AH6: =VLOOKUP(B6,拍照客户_业务级!$A$9:$KF$30,214,FALSE) -> -2.5759594 | AI6: =VLOOKUP(B6,拍照客户_业务级!$A$9:$KF$30,94,FALSE) -> 93.476329 | AJ6: =VLOOKUP(B6,拍照客户_业务级!$A$9:$KF$30,96,FALSE) -> -0.2031703 | AK6: =VLOOKUP(B6,拍照客户_业务级!$A$9:$KF$30,95,FALSE) -> -1.6989856 | AL6: =VLOOKUP(B6,拍照客户_业务级!$A$9:$KF$30,221,FALSE) -> 98.588225 | AM6: =VLOOKUP(B6,拍照客户_业务级!$A$9:$KF$30,223,FALSE) -> -0.39257595 | AN6: =VLOOKUP(B6,拍照客户_业务级!$A$9:$KF$30,222,FALSE) -> -7.1088643 | AO6: =VLOOKUP(B6,拍照客户_业务级!$A$9:$KF$30,108,FALSE) -> 94.895357 | AP6: =VLOOKUP(B6,拍照客户_业务级!$A$9:$KF$30,110,FALSE) -> -1.0698173 | AQ6: =VLOOKUP(B6,拍照客户_业务级!$A$9:$KF$30,109,FALSE) -> 1.3771926 | AR6: =VLOOKUP(B6,拍照客户_业务级!$A$9:$KF$30,227,FALSE) -> 93.671648 | AS6: =VLOOKUP(B6,拍照客户_业务级!$A$9:$KF$30,229,FALSE) -> -0.44278627 | AT6: =VLOOKUP(B6,拍照客户_业务级!$A$9:$KF$30,228,FALSE) -> 0.88648265 | AU6: =VLOOKUP(B6,拍照客户_业务级!$A$9:$KF$30,118,FALSE) -> 95.41379 | AV6: =VLOOKUP(B6,拍照客户_业务级!$A$9:$KF$30,120,FALSE) -> -0.35201672 | AW6: =VLOOKUP(B6,拍照客户_业务级!$A$9:$KF$30,119,FALSE) -> -0.37184022 | AX6: =VLOOKUP(B6,拍照客户_业务级!$A$9:$KF$30,254,FALSE) -> 96.433411 | AY6: =VLOOKUP(B6,拍照客户_业务级!$A$9:$KF$30,256,FALSE) -> -0.23761725 | AZ6: =VLOOKUP(B6,拍照客户_业务级!$A$9:$KF$30,255,FALSE) -> -1.7946507 | BA6: =VLOOKUP(B6,拍照客户_业务级!$A$9:$KF$30,233,FALSE) -> 101.50342 | BB6: =VLOOKUP(B6,拍照客户_业务级!$A$9:$KF$30,235,FALSE) -> -0.24625971 | BC6: =VLOOKUP(B6,拍照客户_业务级!$A$9:$KF$30,234,FALSE) -> -0.021729924 | BD6: =VLOOKUP(B6,拍照客户_业务级!$A$9:$KF$30,123,FALSE) -> 99.396654 | BE6: =VLOOKUP(B6,拍照客户_业务级!$A$9:$KF$30,125,FALSE) -> 0.2559649 | BF6: =VLOOKUP(B6,拍照客户_业务级!$A$9:$KF$30,124,FALSE) -> -0.56727404 | BG6: =VLOOKUP(B6,拍照客户_业务级!$A$9:$KF$30,239,FALSE) -> 91.482549 | BH6: =VLOOKUP(B6,拍照客户_业务级!$A$9:$KF$30,241,FALSE) -> -0.22917788 | BI6: =VLOOKUP(B6,拍照客户_业务级!$A$9:$KF$30,240,FALSE) -> -3.569502 | BJ6: =VLOOKUP(B6,拍照客户_业务级!$A$9:$KF$30,128,FALSE) -> 96.861594 | BK6: =VLOOKUP(B6,拍照客户_业务级!$A$9:$KF$30,130,FALSE) -> -3.5979835 | BL6: =VLOOKUP(B6,拍照客户_业务级!$A$9:$KF$30,129,FALSE) -> -2.1423553 | BM6: =VLOOKUP(B6,拍照客户_业务级!$A$9:$KF$30,245,FALSE) -> 93.717386 | BN6: =VLOOKUP(B6,拍照客户_业务级!$A$9:$KF$30,247,FALSE) -> -0.21798736 | BO6: =VLOOKUP(B6,拍照客户_业务级!$A$9:$KF$30,246,FALSE) -> -14.68014
B7: 佛山 | C7: =ROUND(VLOOKUP(B7,拍照客户_客户级!$A$2:$BX$27,28,FALSE)/10000,3) -> 174.808 | D7: =ROUND(VLOOKUP(B7,拍照客户_客户级!$A$2:$BX$27,29,FALSE)/10000,3) -> 5811.619 | E7: =ROUND(VLOOKUP(B7,拍照客户_客户级!$A$2:$BX$27,30,FALSE)/10000,3) -> -5299.155 | F7: =ROUND(VLOOKUP(B7,拍照客户_客户级!$A$2:$BX$27,33,FALSE)/10000,3) -> -536.981 | G7: =ROUND(VLOOKUP(B7,拍照客户_客户级!$A$2:$BX$27,31,FALSE)/10000,3) -> 274.564 | H7: =ROUND(VLOOKUP(B7,拍照客户_客户级!$A$2:$BX$27,32,FALSE)/10000,3) -> -75.239 | I7: =VLOOKUP(B7,拍照客户_客户级!$A$2:$BX$27,13,FALSE) -> 94.527947 | J7: =VLOOKUP(B7,拍照客户_客户级!$A$2:$BX$27,15,FALSE) -> -0.70230249 | K7: =VLOOKUP(B7,拍照客户_客户级!$A$2:$BX$27,14,FALSE) -> 0.25840005 | L7: =VLOOKUP(B7,拍照客户_客户级!$A$2:$BX$27,34,FALSE) -> 100.2702 | M7: =VLOOKUP(B7,拍照客户_客户级!$A$2:$BX$27,36,FALSE) -> -0.51027213 | N7: =VLOOKUP(B7,拍照客户_客户级!$A$2:$BX$27,35,FALSE) -> 6.3295876 | O7: =VLOOKUP(B7,拍照客户_客户级!$A$2:$BX$27,49,FALSE) -> -0.62926234 | P7: =VLOOKUP(B7,拍照客户_客户级!$A$2:$BX$27,50,FALSE) -> 0.4521459 | Q7: =VLOOKUP(B7,拍照客户_客户级!$A$2:$BX$27,51,FALSE) -> 8.7680676 | R7: =VLOOKUP(B7,拍照客户_客户级!$A$2:$BX$27,52,FALSE) -> -8.3446817 | S7: =VLOOKUP(B7,拍照客户_客户级!$A$2:$BX$27,55,FALSE) -> -1.0814082 | T7: =VLOOKUP(B7,拍照客户_业务级!$A$9:$KF$30,282,FALSE) -> -1.5532436 | U7: =VLOOKUP(B7,拍照客户_业务级!$A$9:$KF$30,284,FALSE) -> 0.69644485 | V7: =VLOOKUP(B7,拍照客户_业务级!$A$9:$KF$30,285,FALSE) -> -0.13713825 | W7: =VLOOKUP(B7,拍照客户_业务级!$A$9:$KF$30,251,FALSE) -> 98.672137 | X7: =VLOOKUP(B7,拍照客户_业务级!$A$9:$KF$30,253,FALSE) -> -0.23600806 | Y7: =VLOOKUP(B7,拍照客户_业务级!$A$9:$KF$30,252,FALSE) -> 1.0971081 | Z7: =VLOOKUP(B7,拍照客户_业务级!$A$9:$KF$30,204,FALSE) -> 100.21363 | AA7: =VLOOKUP(B7,拍照客户_业务级!$A$9:$KF$30,206,FALSE) -> -0.059134118 | AB7: =VLOOKUP(B7,拍照客户_业务级!$A$9:$KF$30,205,FALSE) -> -0.92932 | AC7: =VLOOKUP(B7,拍照客户_业务级!$A$9:$KF$30,78,FALSE) -> 96.411565 | AD7: =VLOOKUP(B7,拍照客户_业务级!$A$9:$KF$30,80,FALSE) -> -0.33328834 | AE7: =VLOOKUP(B7,拍照客户_业务级!$A$9:$KF$30,79,FALSE) -> -0.81646411 | AF7: =VLOOKUP(B7,拍照客户_业务级!$A$9:$KF$30,213,FALSE) -> 102.65568 | AG7: =VLOOKUP(B7,拍照客户_业务级!$A$9:$KF$30,215,FALSE) -> -0.51971268 | AH7: =VLOOKUP(B7,拍照客户_业务级!$A$9:$KF$30,214,FALSE) -> 5.1080814 | AI7: =VLOOKUP(B7,拍照客户_业务级!$A$9:$KF$30,94,FALSE) -> 96.442866 | AJ7: =VLOOKUP(B7,拍照客户_业务级!$A$9:$KF$30,96,FALSE) -> -1.0395355 | AK7: =VLOOKUP(B7,拍照客户_业务级!$A$9:$KF$30,95,FALSE) -> 1.3829833 | AL7: =VLOOKUP(B7,拍照客户_业务级!$A$9:$KF$30,221,FALSE) -> 99.263942 | AM7: =VLOOKUP(B7,拍照客户_业务级!$A$9:$KF$30,223,FALSE) -> -0.48196719 | AN7: =VLOOKUP(B7,拍照客户_业务级!$A$9:$KF$30,222,FALSE) -> -4.8533498 | AO7: =VLOOKUP(B7,拍照客户_业务级!$A$9:$KF$30,108,FALSE) -> 89.275087 | AP7: =VLOOKUP(B7,拍照客户_业务级!$A$9:$KF$30,110,FALSE) -> -2.7041399 | AQ7: =VLOOKUP(B7,拍照客户_业务级!$A$9:$KF$30,109,FALSE) -> -5.1316582 | AR7: =VLOOKUP(B7,拍照客户_业务级!$A$9:$KF$30,227,FALSE) -> 91.721843 | AS7: =VLOOKUP(B7,拍照客户_业务级!$A$9:$KF$30,229,FALSE) -> -0.49728695 | AT7: =VLOOKUP(B7,拍照客户_业务级!$A$9:$KF$30,228,FALSE) -> 2.9753953 | AU7: =VLOOKUP(B7,拍照客户_业务级!$A$9:$KF$30,118,FALSE) -> 95.444088 | AV7: =VLOOKUP(B7,拍照客户_业务级!$A$9:$KF$30,120,FALSE) -> -0.50039967 | AW7: =VLOOKUP(B7,拍照客户_业务级!$A$9:$KF$30,119,FALSE) -> 0.16891684 | AX7: =VLOOKUP(B7,拍照客户_业务级!$A$9:$KF$30,254,FALSE) -> 102.7528 | AY7: =VLOOKUP(B7,拍照客户_业务级!$A$9:$KF$30,256,FALSE) -> -1.0847802 | AZ7: =VLOOKUP(B7,拍照客户_业务级!$A$9:$KF$30,255,FALSE) -> 8.0346519 | BA7: =VLOOKUP(B7,拍照客户_业务级!$A$9:$KF$30,233,FALSE) -> 103.48742 | BB7: =VLOOKUP(B7,拍照客户_业务级!$A$9:$KF$30,235,FALSE) -> -0.71558087 | BC7: =VLOOKUP(B7,拍照客户_业务级!$A$9:$KF$30,234,FALSE) -> 4.1455868 | BD7: =VLOOKUP(B7,拍照客户_业务级!$A$9:$KF$30,123,FALSE) -> 100.20308 | BE7: =VLOOKUP(B7,拍照客户_业务级!$A$9:$KF$30,125,FALSE) -> 0.1740644 | BF7: =VLOOKUP(B7,拍照客户_业务级!$A$9:$KF$30,124,FALSE) -> 5.5204775 | BG7: =VLOOKUP(B7,拍照客户_业务级!$A$9:$KF$30,239,FALSE) -> 101.81629 | BH7: =VLOOKUP(B7,拍照客户_业务级!$A$9:$KF$30,241,FALSE) -> -1.5554419 | BI7: =VLOOKUP(B7,拍照客户_业务级!$A$9:$KF$30,240,FALSE) -> 12.509662 | BJ7: =VLOOKUP(B7,拍照客户_业务级!$A$9:$KF$30,128,FALSE) -> 88.956029 | BK7: =VLOOKUP(B7,拍照客户_业务级!$A$9:$KF$30,130,FALSE) -> 0.25082659 | BL7: =VLOOKUP(B7,拍照客户_业务级!$A$9:$KF$30,129,FALSE) -> -7.2163885 | BM7: =VLOOKUP(B7,拍照客户_业务级!$A$9:$KF$30,245,FALSE) -> 102.5734 | BN7: =VLOOKUP(B7,拍照客户_业务级!$A$9:$KF$30,247,FALSE) -> -0.49741704 | BO7: =VLOOKUP(B7,拍照客户_业务级!$A$9:$KF$30,246,FALSE) -> 29.425904
A8: 珠二 | B8: 中山 | C8: =ROUND(VLOOKUP(B8,拍照客户_客户级!$A$2:$BX$27,28,FALSE)/10000,3) -> 478.83 | D8: =ROUND(VLOOKUP(B8,拍照客户_客户级!$A$2:$BX$27,29,FALSE)/10000,3) -> 2556.74 | E8: =ROUND(VLOOKUP(B8,拍照客户_客户级!$A$2:$BX$27,30,FALSE)/10000,3) -> -1866.573 | F8: =ROUND(VLOOKUP(B8,拍照客户_客户级!$A$2:$BX$27,33,FALSE)/10000,3) -> -322.033 | G8: =ROUND(VLOOKUP(B8,拍照客户_客户级!$A$2:$BX$27,31,FALSE)/10000,3) -> 169.765 | H8: =ROUND(VLOOKUP(B8,拍照客户_客户级!$A$2:$BX$27,32,FALSE)/10000,3) -> -59.068 | I8: =VLOOKUP(B8,拍照客户_客户级!$A$2:$BX$27,13,FALSE) -> 94.168988 | J8: =VLOOKUP(B8,拍照客户_客户级!$A$2:$BX$27,15,FALSE) -> -1.1424855 | K8: =VLOOKUP(B8,拍照客户_客户级!$A$2:$BX$27,14,FALSE) -> 0.10478832 | L8: =VLOOKUP(B8,拍照客户_客户级!$A$2:$BX$27,34,FALSE) -> 101.58241 | M8: =VLOOKUP(B8,拍照客户_客户级!$A$2:$BX$27,36,FALSE) -> -0.34501605 | N8: =VLOOKUP(B8,拍照客户_客户级!$A$2:$BX$27,35,FALSE) -> 1.8198524 | O8: =VLOOKUP(B8,拍照客户_客户级!$A$2:$BX$27,49,FALSE) -> 0.77486075 | P8: =VLOOKUP(B8,拍照客户_客户级!$A$2:$BX$27,50,FALSE) -> 1.9151635 | Q8: =VLOOKUP(B8,拍照客户_客户级!$A$2:$BX$27,51,FALSE) -> 8.2062594 | R8: =VLOOKUP(B8,拍照客户_客户级!$A$2:$BX$27,52,FALSE) -> -6.3634979 | S8: =VLOOKUP(B8,拍照客户_客户级!$A$2:$BX$27,55,FALSE) -> -1.1403028 | T8: =VLOOKUP(B8,拍照客户_业务级!$A$9:$KF$30,282,FALSE) -> -0.81932393 | U8: =VLOOKUP(B8,拍照客户_业务级!$A$9:$KF$30,284,FALSE) -> 1.0520678 | V8: =VLOOKUP(B8,拍照客户_业务级!$A$9:$KF$30,285,FALSE) -> -0.3854127 | W8: =VLOOKUP(B8,拍照客户_业务级!$A$9:$KF$30,251,FALSE) -> 99.890867 | X8: =VLOOKUP(B8,拍照客户_业务级!$A$9:$KF$30,253,FALSE) -> -0.29218063 | Y8: =VLOOKUP(B8,拍照客户_业务级!$A$9:$KF$30,252,FALSE) -> -0.12486316 | Z8: =VLOOKUP(B8,拍照客户_业务级!$A$9:$KF$30,204,FALSE) -> 101.35635 | AA8: =VLOOKUP(B8,拍照客户_业务级!$A$9:$KF$30,206,FALSE) -> -0.28450674 | AB8: =VLOOKUP(B8,拍照客户_业务级!$A$9:$KF$30,205,FALSE) -> -0.62254921 | AC8: =VLOOKUP(B8,拍照客户_业务级!$A$9:$KF$30,78,FALSE) -> 95.296449 | AD8: =VLOOKUP(B8,拍照客户_业务级!$A$9:$KF$30,80,FALSE) -> -1.2089519 | AE8: =VLOOKUP(B8,拍照客户_业务级!$A$9:$KF$30,79,FALSE) -> -1.1472591 | AF8: =VLOOKUP(B8,拍照客户_业务级!$A$9:$KF$30,213,FALSE) -> 104.92848 | AG8: =VLOOKUP(B8,拍照客户_业务级!$A$9:$KF$30,215,FALSE) -> -0.33757211 | AH8: =VLOOKUP(B8,拍照客户_业务级!$A$9:$KF$30,214,FALSE) -> 2.3930337 | AI8: =VLOOKUP(B8,拍照客户_业务级!$A$9:$KF$30,94,FALSE) -> 96.425786 | AJ8: =VLOOKUP(B8,拍照客户_业务级!$A$9:$KF$30,96,FALSE) -> -0.87126699 | AK8: =VLOOKUP(B8,拍照客户_业务级!$A$9:$KF$30,95,FALSE) -> 1.8001952 | AL8: =VLOOKUP(B8,拍照客户_业务级!$A$9:$KF$30,221,FALSE) -> 101.04394 | AM8: =VLOOKUP(B8,拍照客户_业务级!$A$9:$KF$30,223,FALSE) -> -0.45400147 | AN8: =VLOOKUP(B8,拍照客户_业务级!$A$9:$KF$30,222,FALSE) -> -5.594926 | AO8: =VLOOKUP(B8,拍照客户_业务级!$A$9:$KF$30,108,FALSE) -> 90.836336 | AP8: =VLOOKUP(B8,拍照客户_业务级!$A$9:$KF$30,110,FALSE) -> -3.1431086 | AQ8: =VLOOKUP(B8,拍照客户_业务级!$A$9:$KF$30,109,FALSE) -> -1.9597312 | AR8: =VLOOKUP(B8,拍照客户_业务级!$A$9:$KF$30,227,FALSE) -> 91.156374 | AS8: =VLOOKUP(B8,拍照客户_业务级!$A$9:$KF$30,229,FALSE) -> -0.25872565 | AT8: =VLOOKUP(B8,拍照客户_业务级!$A$9:$KF$30,228,FALSE) -> -1.3828615 | AU8: =VLOOKUP(B8,拍照客户_业务级!$A$9:$KF$30,118,FALSE) -> 95.957913 | AV8: =VLOOKUP(B8,拍照客户_业务级!$A$9:$KF$30,120,FALSE) -> -0.38577649 | AW8: =VLOOKUP(B8,拍照客户_业务级!$A$9:$KF$30,119,FALSE) -> 5.6019986 | AX8: =VLOOKUP(B8,拍照客户_业务级!$A$9:$KF$30,254,FALSE) -> 105.56223 | AY8: =VLOOKUP(B8,拍照客户_业务级!$A$9:$KF$30,256,FALSE) -> -0.046416937 | AZ8: =VLOOKUP(B8,拍照客户_业务级!$A$9:$KF$30,255,FALSE) -> 4.571521 | BA8: =VLOOKUP(B8,拍照客户_业务级!$A$9:$KF$30,233,FALSE) -> 107.04998 | BB8: =VLOOKUP(B8,拍照客户_业务级!$A$9:$KF$30,235,FALSE) -> 0.028243528 | BC8: =VLOOKUP(B8,拍照客户_业务级!$A$9:$KF$30,234,FALSE) -> 2.5545561 | BD8: =VLOOKUP(B8,拍照客户_业务级!$A$9:$KF$30,123,FALSE) -> 105.2081 | BE8: =VLOOKUP(B8,拍照客户_业务级!$A$9:$KF$30,125,FALSE) -> -1.4689517 | BF8: =VLOOKUP(B8,拍照客户_业务级!$A$9:$KF$30,124,FALSE) -> -0.13631656 | BG8: =VLOOKUP(B8,拍照客户_业务级!$A$9:$KF$30,239,FALSE) -> 103.47311 | BH8: =VLOOKUP(B8,拍照客户_业务级!$A$9:$KF$30,241,FALSE) -> -0.15125717 | BI8: =VLOOKUP(B8,拍照客户_业务级!$A$9:$KF$30,240,FALSE) -> 7.0790975 | BJ8: =VLOOKUP(B8,拍照客户_业务级!$A$9:$KF$30,128,FALSE) -> 99.57484 | BK8: =VLOOKUP(B8,拍照客户_业务级!$A$9:$KF$30,130,FALSE) -> -0.9496563 | BL8: =VLOOKUP(B8,拍照客户_业务级!$A$9:$KF$30,129,FALSE) -> -5.5628574 | BM8: =VLOOKUP(B8,拍照客户_业务级!$A$9:$KF$30,245,FALSE) -> 105.09772 | BN8: =VLOOKUP(B8,拍照客户_业务级!$A$9:$KF$30,247,FALSE) -> -1.1964544 | BO8: =VLOOKUP(B8,拍照客户_业务级!$A$9:$KF$30,246,FALSE) -> 9.5490405
B9: 惠州 | C9: =ROUND(VLOOKUP(B9,拍照客户_客户级!$A$2:$BX$27,28,FALSE)/10000,3) -> -1545.834 | D9: =ROUND(VLOOKUP(B9,拍照客户_客户级!$A$2:$BX$27,29,FALSE)/10000,3) -> 2680.002 | E9: =ROUND(VLOOKUP(B9,拍照客户_客户级!$A$2:$BX$27,30,FALSE)/10000,3) -> -4070.164 | F9: =ROUND(VLOOKUP(B9,拍照客户_客户级!$A$2:$BX$27,33,FALSE)/10000,3) -> -360.213 | G9: =ROUND(VLOOKUP(B9,拍照客户_客户级!$A$2:$BX$27,31,FALSE)/10000,3) -> 170.606 | H9: =ROUND(VLOOKUP(B9,拍照客户_客户级!$A$2:$BX$27,32,FALSE)/10000,3) -> 33.936 | I9: =VLOOKUP(B9,拍照客户_客户级!$A$2:$BX$27,13,FALSE) -> 92.253347 | J9: =VLOOKUP(B9,拍照客户_客户级!$A$2:$BX$27,15,FALSE) -> -1.0169197 | K9: =VLOOKUP(B9,拍照客户_客户级!$A$2:$BX$27,14,FALSE) -> 1.4471112 | L9: =VLOOKUP(B9,拍照客户_客户级!$A$2:$BX$27,34,FALSE) -> 95.791252 | M9: =VLOOKUP(B9,拍照客户_客户级!$A$2:$BX$27,36,FALSE) -> -0.71746306 | N9: =VLOOKUP(B9,拍照客户_客户级!$A$2:$BX$27,35,FALSE) -> -4.4052581 | O9: =VLOOKUP(B9,拍照客户_客户级!$A$2:$BX$27,49,FALSE) -> -7.9840509 | P9: =VLOOKUP(B9,拍照客户_客户级!$A$2:$BX$27,50,FALSE) -> -6.8650899 | Q9: =VLOOKUP(B9,拍照客户_客户级!$A$2:$BX$27,51,FALSE) -> 6.9202342 | R9: =VLOOKUP(B9,拍照客户_客户级!$A$2:$BX$27,52,FALSE) -> -13.84277 | S9: =VLOOKUP(B9,拍照客户_客户级!$A$2:$BX$27,55,FALSE) -> -1.1189611 | T9: =VLOOKUP(B9,拍照客户_业务级!$A$9:$KF$30,282,FALSE) -> -0.25173757 | U9: =VLOOKUP(B9,拍照客户_业务级!$A$9:$KF$30,284,FALSE) -> -3.2266236 | V9: =VLOOKUP(B9,拍照客户_业务级!$A$9:$KF$30,285,FALSE) -> -5.863236 | W9: =VLOOKUP(B9,拍照客户_业务级!$A$9:$KF$30,251,FALSE) -> 100.94645 | X9: =VLOOKUP(B9,拍照客户_业务级!$A$9:$KF$30,253,FALSE) -> -0.25110873 | Y9: =VLOOKUP(B9,拍照客户_业务级!$A$9:$KF$30,252,FALSE) -> 0.58251264 | Z9: =VLOOKUP(B9,拍照客户_业务级!$A$9:$KF$30,204,FALSE) -> 105.73919 | AA9: =VLOOKUP(B9,拍照客户_业务级!$A$9:$KF$30,206,FALSE) -> -0.1990376 | AB9: =VLOOKUP(B9,拍照客户_业务级!$A$9:$KF$30,205,FALSE) -> 0.83428285 | AC9: =VLOOKUP(B9,拍照客户_业务级!$A$9:$KF$30,78,FALSE) -> 94.606209 | AD9: =VLOOKUP(B9,拍照客户_业务级!$A$9:$KF$30,80,FALSE) -> -0.53169245 | AE9: =VLOOKUP(B9,拍照客户_业务级!$A$9:$KF$30,79,FALSE) -> -0.59492206 | AF9: =VLOOKUP(B9,拍照客户_业务级!$A$9:$KF$30,213,FALSE) -> 97.07594 | AG9: =VLOOKUP(B9,拍照客户_业务级!$A$9:$KF$30,215,FALSE) -> -0.2741284 | AH9: =VLOOKUP(B9,拍照客户_业务级!$A$9:$KF$30,214,FALSE) -> 1.1722169 | AI9: =VLOOKUP(B9,拍照客户_业务级!$A$9:$KF$30,94,FALSE) -> 95.006745 | AJ9: =VLOOKUP(B9,拍照客户_业务级!$A$9:$KF$30,96,FALSE) -> -0.6988419 | AK9: =VLOOKUP(B9,拍照客户_业务级!$A$9:$KF$30,95,FALSE) -> -0.046660494 | AL9: =VLOOKUP(B9,拍照客户_业务级!$A$9:$KF$30,221,FALSE) -> 93.609649 | AM9: =VLOOKUP(B9,拍照客户_业务级!$A$9:$KF$30,223,FALSE) -> -0.73436625 | AN9: =VLOOKUP(B9,拍照客户_业务级!$A$9:$KF$30,222,FALSE) -> -11.361332 | AO9: =VLOOKUP(B9,拍照客户_业务级!$A$9:$KF$30,108,FALSE) -> 90.256281 | AP9: =VLOOKUP(B9,拍照客户_业务级!$A$9:$KF$30,110,FALSE) -> -1.9991625 | AQ9: =VLOOKUP(B9,拍照客户_业务级!$A$9:$KF$30,109,FALSE) -> -7.2630216 | AR9: =VLOOKUP(B9,拍照客户_业务级!$A$9:$KF$30,227,FALSE) -> 92.692037 | AS9: =VLOOKUP(B9,拍照客户_业务级!$A$9:$KF$30,229,FALSE) -> -0.32146266 | AT9: =VLOOKUP(B9,拍照客户_业务级!$A$9:$KF$30,228,FALSE) -> -0.75810483 | AU9: =VLOOKUP(B9,拍照客户_业务级!$A$9:$KF$30,118,FALSE) -> 95.871175 | AV9: =VLOOKUP(B9,拍照客户_业务级!$A$9:$KF$30,120,FALSE) -> -0.73955354 | AW9: =VLOOKUP(B9,拍照客户_业务级!$A$9:$KF$30,119,FALSE) -> 0.060096548 | AX9: =VLOOKUP(B9,拍照客户_业务级!$A$9:$KF$30,254,FALSE) -> 89.298299 | AY9: =VLOOKUP(B9,拍照客户_业务级!$A$9:$KF$30,256,FALSE) -> -1.1729447 | AZ9: =VLOOKUP(B9,拍照客户_业务级!$A$9:$KF$30,255,FALSE) -> -10.162088 | BA9: =VLOOKUP(B9,拍照客户_业务级!$A$9:$KF$30,233,FALSE) -> 95.843305 | BB9: =VLOOKUP(B9,拍照客户_业务级!$A$9:$KF$30,235,FALSE) -> -0.30757745 | BC9: =VLOOKUP(B9,拍照客户_业务级!$A$9:$KF$30,234,FALSE) -> 1.4635676 | BD9: =VLOOKUP(B9,拍照客户_业务级!$A$9:$KF$30,123,FALSE) -> 106.09398 | BE9: =VLOOKUP(B9,拍照客户_业务级!$A$9:$KF$30,125,FALSE) -> -1.1502692 | BF9: =VLOOKUP(B9,拍照客户_业务级!$A$9:$KF$30,124,FALSE) -> 13.486421 | BG9: =VLOOKUP(B9,拍照客户_业务级!$A$9:$KF$30,239,FALSE) -> 83.305446 | BH9: =VLOOKUP(B9,拍照客户_业务级!$A$9:$KF$30,241,FALSE) -> -1.9653075 | BI9: =VLOOKUP(B9,拍照客户_业务级!$A$9:$KF$30,240,FALSE) -> -21.360397 | BJ9: =VLOOKUP(B9,拍照客户_业务级!$A$9:$KF$30,128,FALSE) -> 91.518685 | BK9: =VLOOKUP(B9,拍照客户_业务级!$A$9:$KF$30,130,FALSE) -> -0.26945843 | BL9: =VLOOKUP(B9,拍照客户_业务级!$A$9:$KF$30,129,FALSE) -> -13.68997 | BM9: =VLOOKUP(B9,拍照客户_业务级!$A$9:$KF$30,245,FALSE) -> 83.560797 | BN9: =VLOOKUP(B9,拍照客户_业务级!$A$9:$KF$30,247,FALSE) -> -2.2887371 | BO9: =VLOOKUP(B9,拍照客户_业务级!$A$9:$KF$30,246,FALSE) -> -18.734742
B10: 江门 | C10: =ROUND(VLOOKUP(B10,拍照客户_客户级!$A$2:$BX$27,28,FALSE)/10000,3) -> 830.714 | D10: =ROUND(VLOOKUP(B10,拍照客户_客户级!$A$2:$BX$27,29,FALSE)/10000,3) -> 2814.36 | E10: =ROUND(VLOOKUP(B10,拍照客户_客户级!$A$2:$BX$27,30,FALSE)/10000,3) -> -1919.242 | F10: =ROUND(VLOOKUP(B10,拍照客户_客户级!$A$2:$BX$27,33,FALSE)/10000,3) -> -430.521 | G10: =ROUND(VLOOKUP(B10,拍照客户_客户级!$A$2:$BX$27,31,FALSE)/10000,3) -> 321.298 | H10: =ROUND(VLOOKUP(B10,拍照客户_客户级!$A$2:$BX$27,32,FALSE)/10000,3) -> 44.819 | I10: =VLOOKUP(B10,拍照客户_客户级!$A$2:$BX$27,13,FALSE) -> 92.924439 | J10: =VLOOKUP(B10,拍照客户_客户级!$A$2:$BX$27,15,FALSE) -> -0.91952336 | K10: =VLOOKUP(B10,拍照客户_客户级!$A$2:$BX$27,14,FALSE) -> 0.97899388 | L10: =VLOOKUP(B10,拍照客户_客户级!$A$2:$BX$27,34,FALSE) -> 102.89372 | M10: =VLOOKUP(B10,拍照客户_客户级!$A$2:$BX$27,36,FALSE) -> -0.26911596 | N10: =VLOOKUP(B10,拍照客户_客户级!$A$2:$BX$27,35,FALSE) -> -2.532919 | O10: =VLOOKUP(B10,拍照客户_客户级!$A$2:$BX$27,49,FALSE) -> 0.9806016 | P10: =VLOOKUP(B10,拍照客户_客户级!$A$2:$BX$27,50,FALSE) -> 2.6332536 | Q10: =VLOOKUP(B10,拍照客户_客户级!$A$2:$BX$27,51,FALSE) -> 9.4813888 | R10: =VLOOKUP(B10,拍照客户_客户级!$A$2:$BX$27,52,FALSE) -> -6.9814806 | S10: =VLOOKUP(B10,拍照客户_客户级!$A$2:$BX$27,55,FALSE) -> -1.652652 | T10: =VLOOKUP(B10,拍照客户_业务级!$A$9:$KF$30,282,FALSE) -> -0.17547021 | U10: =VLOOKUP(B10,拍照客户_业务级!$A$9:$KF$30,284,FALSE) -> 2.0186879 | V10: =VLOOKUP(B10,拍照客户_业务级!$A$9:$KF$30,285,FALSE) -> -1.2424651 | W10: =VLOOKUP(B10,拍照客户_业务级!$A$9:$KF$30,251,FALSE) -> 102.26639 | X10: =VLOOKUP(B10,拍照客户_业务级!$A$9:$KF$30,253,FALSE) -> -0.38286344 | Y10: =VLOOKUP(B10,拍照客户_业务级!$A$9:$KF$30,252,FALSE) -> 1.3109258 | Z10: =VLOOKUP(B10,拍照客户_业务级!$A$9:$KF$30,204,FALSE) -> 104.07863 | AA10: =VLOOKUP(B10,拍照客户_业务级!$A$9:$KF$30,206,FALSE) -> -0.18706639 | AB10: =VLOOKUP(B10,拍照客户_业务级!$A$9:$KF$30,205,FALSE) -> 1.4625241 | AC10: =VLOOKUP(B10,拍照客户_业务级!$A$9:$KF$30,78,FALSE) -> 95.000186 | AD10: =VLOOKUP(B10,拍照客户_业务级!$A$9:$KF$30,80,FALSE) -> -0.682402 | AE10: =VLOOKUP(B10,拍照客户_业务级!$A$9:$KF$30,79,FALSE) -> -0.14702793 | AF10: =VLOOKUP(B10,拍照客户_业务级!$A$9:$KF$30,213,FALSE) -> 106.69191 | AG10: =VLOOKUP(B10,拍照客户_业务级!$A$9:$KF$30,215,FALSE) -> -0.5419063 | AH10: =VLOOKUP(B10,拍照客户_业务级!$A$9:$KF$30,214,FALSE) -> 6.0204497 | AI10: =VLOOKUP(B10,拍照客户_业务级!$A$9:$KF$30,94,FALSE) -> 95.436707 | AJ10: =VLOOKUP(B10,拍照客户_业务级!$A$9:$KF$30,96,FALSE) -> -1.095956 | AK10: =VLOOKUP(B10,拍照客户_业务级!$A$9:$KF$30,95,FALSE) -> 2.7288316 | AL10: =VLOOKUP(B10,拍照客户_业务级!$A$9:$KF$30,221,FALSE) -> 99.115007 | AM10: =VLOOKUP(B10,拍照客户_业务级!$A$9:$KF$30,223,FALSE) -> -0.18356529 | AN10: =VLOOKUP(B10,拍照客户_业务级!$A$9:$KF$30,222,FALSE) -> -3.5479019 | AO10: =VLOOKUP(B10,拍照客户_业务级!$A$9:$KF$30,108,FALSE) -> 89.69914 | AP10: =VLOOKUP(B10,拍照客户_业务级!$A$9:$KF$30,110,FALSE) -> -2.4054441 | AQ10: =VLOOKUP(B10,拍照客户_业务级!$A$9:$KF$30,109,FALSE) -> -3.2107072 | AR10: =VLOOKUP(B10,拍照客户_业务级!$A$9:$KF$30,227,FALSE) -> 91.353856 | AS10: =VLOOKUP(B10,拍照客户_业务级!$A$9:$KF$30,229,FALSE) -> -0.872705 | AT10: =VLOOKUP(B10,拍照客户_业务级!$A$9:$KF$30,228,FALSE) -> -4.436751 | AU10: =VLOOKUP(B10,拍照客户_业务级!$A$9:$KF$30,118,FALSE) -> 96.41598 | AV10: =VLOOKUP(B10,拍照客户_业务级!$A$9:$KF$30,120,FALSE) -> -0.33507409 | AW10: =VLOOKUP(B10,拍照客户_业务级!$A$9:$KF$30,119,FALSE) -> 0.49387769 | AX10: =VLOOKUP(B10,拍照客户_业务级!$A$9:$KF$30,254,FALSE) -> 111.39717 | AY10: =VLOOKUP(B10,拍照客户_业务级!$A$9:$KF$30,256,FALSE) -> 0.36485199 | AZ10: =VLOOKUP(B10,拍照客户_业务级!$A$9:$KF$30,255,FALSE) -> -11.044698 | BA10: =VLOOKUP(B10,拍照客户_业务级!$A$9:$KF$30,233,FALSE) -> 111.85408 | BB10: =VLOOKUP(B10,拍照客户_业务级!$A$9:$KF$30,235,FALSE) -> -0.34667309 | BC10: =VLOOKUP(B10,拍照客户_业务级!$A$9:$KF$30,234,FALSE) -> 4.6339883 | BD10: =VLOOKUP(B10,拍照客户_业务级!$A$9:$KF$30,123,FALSE) -> 101.68067 | BE10: =VLOOKUP(B10,拍照客户_业务级!$A$9:$KF$30,125,FALSE) -> -2.3459384 | BF10: =VLOOKUP(B10,拍照客户_业务级!$A$9:$KF$30,124,FALSE) -> -4.6860834 | BG10: =VLOOKUP(B10,拍照客户_业务级!$A$9:$KF$30,239,FALSE) -> 111.03565 | BH10: =VLOOKUP(B10,拍照客户_业务级!$A$9:$KF$30,241,FALSE) -> 0.92781534 | BI10: =VLOOKUP(B10,拍照客户_业务级!$A$9:$KF$30,240,FALSE) -> -26.277227 | BJ10: =VLOOKUP(B10,拍照客户_业务级!$A$9:$KF$30,128,FALSE) -> 103.4572 | BK10: =VLOOKUP(B10,拍照客户_业务级!$A$9:$KF$30,130,FALSE) -> 0.43273754 | BL10: =VLOOKUP(B10,拍照客户_业务级!$A$9:$KF$30,129,FALSE) -> 7.4847303 | BM10: =VLOOKUP(B10,拍照客户_业务级!$A$9:$KF$30,245,FALSE) -> 89.315064 | BN10: =VLOOKUP(B10,拍照客户_业务级!$A$9:$KF$30,247,FALSE) -> -0.6662137 | BO10: =VLOOKUP(B10,拍照客户_业务级!$A$9:$KF$30,246,FALSE) -> -27.849501
B11: 珠海 | C11: =ROUND(VLOOKUP(B11,拍照客户_客户级!$A$2:$BX$27,28,FALSE)/10000,3) -> -3369.134 | D11: =ROUND(VLOOKUP(B11,拍照客户_客户级!$A$2:$BX$27,29,FALSE)/10000,3) -> 1914.066 | E11: =ROUND(VLOOKUP(B11,拍照客户_客户级!$A$2:$BX$27,30,FALSE)/10000,3) -> -5087.246 | F11: =ROUND(VLOOKUP(B11,拍照客户_客户级!$A$2:$BX$27,33,FALSE)/10000,3) -> -286.324 | G11: =ROUND(VLOOKUP(B11,拍照客户_客户级!$A$2:$BX$27,31,FALSE)/10000,3) -> 108.923 | H11: =ROUND(VLOOKUP(B11,拍照客户_客户级!$A$2:$BX$27,32,FALSE)/10000,3) -> -18.554 | I11: =VLOOKUP(B11,拍照客户_客户级!$A$2:$BX$27,13,FALSE) -> 95.468374 | J11: =VLOOKUP(B11,拍照客户_客户级!$A$2:$BX$27,15,FALSE) -> -0.56023864 | K11: =VLOOKUP(B11,拍照客户_客户级!$A$2:$BX$27,14,FALSE) -> -0.099520426 | L11: =VLOOKUP(B11,拍照客户_客户级!$A$2:$BX$27,34,FALSE) -> 87.833758 | M11: =VLOOKUP(B11,拍照客户_客户级!$A$2:$BX$27,36,FALSE) -> -0.44960202 | N11: =VLOOKUP(B11,拍照客户_客户级!$A$2:$BX$27,35,FALSE) -> -17.969863 | O11: =VLOOKUP(B11,拍照客户_客户级!$A$2:$BX$27,49,FALSE) -> -12.768507 | P11: =VLOOKUP(B11,拍照客户_客户级!$A$2:$BX$27,50,FALSE) -> -11.663613 | Q11: =VLOOKUP(B11,拍照客户_客户级!$A$2:$BX$27,51,FALSE) -> 6.7639347 | R11: =VLOOKUP(B11,拍照客户_客户级!$A$2:$BX$27,52,FALSE) -> -18.429245 | S11: =VLOOKUP(B11,拍照客户_客户级!$A$2:$BX$27,55,FALSE) -> -1.1048931 | T11: =VLOOKUP(B11,拍照客户_业务级!$A$9:$KF$30,282,FALSE) -> -1.8586094 | U11: =VLOOKUP(B11,拍照客户_业务级!$A$9:$KF$30,284,FALSE) -> -7.5659998 | V11: =VLOOKUP(B11,拍照客户_业务级!$A$9:$KF$30,285,FALSE) -> -4.1632352 | W11: =VLOOKUP(B11,拍照客户_业务级!$A$9:$KF$30,251,FALSE) -> 96.74431 | X11: =VLOOKUP(B11,拍照客户_业务级!$A$9:$KF$30,253,FALSE) -> -0.47631766 | Y11: =VLOOKUP(B11,拍照客户_业务级!$A$9:$KF$30,252,FALSE) -> -2.6523585 | Z11: =VLOOKUP(B11,拍照客户_业务级!$A$9:$KF$30,204,FALSE) -> 99.676953 | AA11: =VLOOKUP(B11,拍照客户_业务级!$A$9:$KF$30,206,FALSE) -> -0.40146552 | AB11: =VLOOKUP(B11,拍照客户_业务级!$A$9:$KF$30,205,FALSE) -> -2.9596952 | AC11: =VLOOKUP(B11,拍照客户_业务级!$A$9:$KF$30,78,FALSE) -> 93.834172 | AD11: =VLOOKUP(B11,拍照客户_业务级!$A$9:$KF$30,80,FALSE) -> -0.65529812 | AE11: =VLOOKUP(B11,拍照客户_业务级!$A$9:$KF$30,79,FALSE) -> 0.10209151 | AF11: =VLOOKUP(B11,拍照客户_业务级!$A$9:$KF$30,213,FALSE) -> 102.08065 | AG11: =VLOOKUP(B11,拍照客户_业务级!$A$9:$KF$30,215,FALSE) -> -0.37507726 | AH11: =VLOOKUP(B11,拍照客户_业务级!$A$9:$KF$30,214,FALSE) -> 0.37709187 | AI11: =VLOOKUP(B11,拍照客户_业务级!$A$9:$KF$30,94,FALSE) -> 98.379408 | AJ11: =VLOOKUP(B11,拍照客户_业务级!$A$9:$KF$30,96,FALSE) -> -0.58693483 | AK11: =VLOOKUP(B11,拍照客户_业务级!$A$9:$KF$30,95,FALSE) -> 1.7250932 | AL11: =VLOOKUP(B11,拍照客户_业务级!$A$9:$KF$30,221,FALSE) -> 100.95147 | AM11: =VLOOKUP(B11,拍照客户_业务级!$A$9:$KF$30,223,FALSE) -> -0.43961306 | AN11: =VLOOKUP(B11,拍照客户_业务级!$A$9:$KF$30,222,FALSE) -> -13.905243 | AO11: =VLOOKUP(B11,拍照客户_业务级!$A$9:$KF$30,108,FALSE) -> 95.398564 | AP11: =VLOOKUP(B11,拍照客户_业务级!$A$9:$KF$30,110,FALSE) -> -0.98787898 | AQ11: =VLOOKUP(B11,拍照客户_业务级!$A$9:$KF$30,109,FALSE) -> -0.068328338 | AR11: =VLOOKUP(B11,拍照客户_业务级!$A$9:$KF$30,227,FALSE) -> 90.127518 | AS11: =VLOOKUP(B11,拍照客户_业务级!$A$9:$KF$30,229,FALSE) -> -0.62631305 | AT11: =VLOOKUP(B11,拍照客户_业务级!$A$9:$KF$30,228,FALSE) -> -3.6223462 | AU11: =VLOOKUP(B11,拍照客户_业务级!$A$9:$KF$30,118,FALSE) -> 96.616403 | AV11: =VLOOKUP(B11,拍照客户_业务级!$A$9:$KF$30,120,FALSE) -> -0.36840563 | AW11: =VLOOKUP(B11,拍照客户_业务级!$A$9:$KF$30,119,FALSE) -> 0.80614068 | AX11: =VLOOKUP(B11,拍照客户_业务级!$A$9:$KF$30,254,FALSE) -> 84.464623 | AY11: =VLOOKUP(B11,拍照客户_业务级!$A$9:$KF$30,256,FALSE) -> -0.29398942 | AZ11: =VLOOKUP(B11,拍照客户_业务级!$A$9:$KF$30,255,FALSE) -> -21.594451 | BA11: =VLOOKUP(B11,拍照客户_业务级!$A$9:$KF$30,233,FALSE) -> 96.625082 | BB11: =VLOOKUP(B11,拍照客户_业务级!$A$9:$KF$30,235,FALSE) -> -0.59100477 | BC11: =VLOOKUP(B11,拍照客户_业务级!$A$9:$KF$30,234,FALSE) -> -3.4867388 | BD11: =VLOOKUP(B11,拍照客户_业务级!$A$9:$KF$30,123,FALSE) -> 95.569374 | BE11: =VLOOKUP(B11,拍照客户_业务级!$A$9:$KF$30,125,FALSE) -> -0.73843762 | BF11: =VLOOKUP(B11,拍照客户_业务级!$A$9:$KF$30,124,FALSE) -> 2.0863109 | BG11: =VLOOKUP(B11,拍照客户_业务级!$A$9:$KF$30,239,FALSE) -> 77.567087 | BH11: =VLOOKUP(B11,拍照客户_业务级!$A$9:$KF$30,241,FALSE) -> -0.12551928 | BI11: =VLOOKUP(B11,拍照客户_业务级!$A$9:$KF$30,240,FALSE) -> -32.357455 | BJ11: =VLOOKUP(B11,拍照客户_业务级!$A$9:$KF$30,128,FALSE) -> 100.68089 | BK11: =VLOOKUP(B11,拍照客户_业务级!$A$9:$KF$30,130,FALSE) -> -0.71802913 | BL11: =VLOOKUP(B11,拍照客户_业务级!$A$9:$KF$30,129,FALSE) -> -1.7555603 | BM11: =VLOOKUP(B11,拍照客户_业务级!$A$9:$KF$30,245,FALSE) -> 71.657801 | BN11: =VLOOKUP(B11,拍照客户_业务级!$A$9:$KF$30,247,FALSE) -> -0.99747254 | BO11: =VLOOKUP(B11,拍照客户_业务级!$A$9:$KF$30,246,FALSE) -> -67.304043
A12: 粤东 | B12: 汕头 | C12: =ROUND(VLOOKUP(B12,拍照客户_客户级!$A$2:$BX$27,28,FALSE)/10000,3) -> 1893.288 | D12: =ROUND(VLOOKUP(B12,拍照客户_客户级!$A$2:$BX$27,29,FALSE)/10000,3) -> 3158.542 | E12: =ROUND(VLOOKUP(B12,拍照客户_客户级!$A$2:$BX$27,30,FALSE)/10000,3) -> -1128.746 | F12: =ROUND(VLOOKUP(B12,拍照客户_客户级!$A$2:$BX$27,33,FALSE)/10000,3) -> -202.366 | G12: =ROUND(VLOOKUP(B12,拍照客户_客户级!$A$2:$BX$27,31,FALSE)/10000,3) -> 76.521 | H12: =ROUND(VLOOKUP(B12,拍照客户_客户级!$A$2:$BX$27,32,FALSE)/10000,3) -> -10.663 | I12: =VLOOKUP(B12,拍照客户_客户级!$A$2:$BX$27,13,FALSE) -> 89.49068 | J12: =VLOOKUP(B12,拍照客户_客户级!$A$2:$BX$27,15,FALSE) -> -1.7450299 | K12: =VLOOKUP(B12,拍照客户_客户级!$A$2:$BX$27,14,FALSE) -> 1.0039387 | L12: =VLOOKUP(B12,拍照客户_客户级!$A$2:$BX$27,34,FALSE) -> 113.63805 | M12: =VLOOKUP(B12,拍照客户_客户级!$A$2:$BX$27,36,FALSE) -> -2.5874415 | N12: =VLOOKUP(B12,拍照客户_客户级!$A$2:$BX$27,35,FALSE) -> 14.585234 | O12: =VLOOKUP(B12,拍照客户_客户级!$A$2:$BX$27,49,FALSE) -> 12.229835 | P12: =VLOOKUP(B12,拍照客户_客户级!$A$2:$BX$27,50,FALSE) -> 13.966465 | Q12: =VLOOKUP(B12,拍照客户_客户级!$A$2:$BX$27,51,FALSE) -> 22.355876 | R12: =VLOOKUP(B12,拍照客户_客户级!$A$2:$BX$27,52,FALSE) -> -8.4340092 | S12: =VLOOKUP(B12,拍照客户_客户级!$A$2:$BX$27,55,FALSE) -> -1.7366299 | T12: =VLOOKUP(B12,拍照客户_业务级!$A$9:$KF$30,282,FALSE) -> -1.8225054 | U12: =VLOOKUP(B12,拍照客户_业务级!$A$9:$KF$30,284,FALSE) -> 12.686473 | V12: =VLOOKUP(B12,拍照客户_业务级!$A$9:$KF$30,285,FALSE) -> 0.078194274 | W12: =VLOOKUP(B12,拍照客户_业务级!$A$9:$KF$30,251,FALSE) -> 98.892079 | X12: =VLOOKUP(B12,拍照客户_业务级!$A$9:$KF$30,253,FALSE) -> -0.16927611 | Y12: =VLOOKUP(B12,拍照客户_业务级!$A$9:$KF$30,252,FALSE) -> -0.33391485 | Z12: =VLOOKUP(B12,拍照客户_业务级!$A$9:$KF$30,204,FALSE) -> 101.83864 | AA12: =VLOOKUP(B12,拍照客户_业务级!$A$9:$KF$30,206,FALSE) -> 0.14293186 | AB12: =VLOOKUP(B12,拍照客户_业务级!$A$9:$KF$30,205,FALSE) -> -0.85681748 | AC12: =VLOOKUP(B12,拍照客户_业务级!$A$9:$KF$30,78,FALSE) -> 95.480672 | AD12: =VLOOKUP(B12,拍照客户_业务级!$A$9:$KF$30,80,FALSE) -> -0.28579046 | AE12: =VLOOKUP(B12,拍照客户_业务级!$A$9:$KF$30,79,FALSE) -> 4.5367223 | AF12: =VLOOKUP(B12,拍照客户_业务级!$A$9:$KF$30,213,FALSE) -> 99.418925 | AG12: =VLOOKUP(B12,拍照客户_业务级!$A$9:$KF$30,215,FALSE) -> -0.3156 | AH12: =VLOOKUP(B12,拍照客户_业务级!$A$9:$KF$30,214,FALSE) -> -0.11124117 | AI12: =VLOOKUP(B12,拍照客户_业务级!$A$9:$KF$30,94,FALSE) -> 93.939139 | AJ12: =VLOOKUP(B12,拍照客户_业务级!$A$9:$KF$30,96,FALSE) -> -2.0792121 | AK12: =VLOOKUP(B12,拍照客户_业务级!$A$9:$KF$30,95,FALSE) -> -1.9174175 | AL12: =VLOOKUP(B12,拍照客户_业务级!$A$9:$KF$30,221,FALSE) -> 97.555673 | AM12: =VLOOKUP(B12,拍照客户_业务级!$A$9:$KF$30,223,FALSE) -> -0.29278294 | AN12: =VLOOKUP(B12,拍照客户_业务级!$A$9:$KF$30,222,FALSE) -> -10.193712 | AO12: =VLOOKUP(B12,拍照客户_业务级!$A$9:$KF$30,108,FALSE) -> 87.944374 | AP12: =VLOOKUP(B12,拍照客户_业务级!$A$9:$KF$30,110,FALSE) -> -1.4722685 | AQ12: =VLOOKUP(B12,拍照客户_业务级!$A$9:$KF$30,109,FALSE) -> -7.5435173 | AR12: =VLOOKUP(B12,拍照客户_业务级!$A$9:$KF$30,227,FALSE) -> 92.702828 | AS12: =VLOOKUP(B12,拍照客户_业务级!$A$9:$KF$30,229,FALSE) -> -0.6649425 | AT12: =VLOOKUP(B12,拍照客户_业务级!$A$9:$KF$30,228,FALSE) -> 0.61892649 | AU12: =VLOOKUP(B12,拍照客户_业务级!$A$9:$KF$30,118,FALSE) -> 95.374738 | AV12: =VLOOKUP(B12,拍照客户_业务级!$A$9:$KF$30,120,FALSE) -> -0.62666975 | AW12: =VLOOKUP(B12,拍照客户_业务级!$A$9:$KF$30,119,FALSE) -> -0.199955 | AX12: =VLOOKUP(B12,拍照客户_业务级!$A$9:$KF$30,254,FALSE) -> 139.46626 | AY12: =VLOOKUP(B12,拍照客户_业务级!$A$9:$KF$30,256,FALSE) -> -7.0422338 | AZ12: =VLOOKUP(B12,拍照客户_业务级!$A$9:$KF$30,255,FALSE) -> 35.784018 | BA12: =VLOOKUP(B12,拍照客户_业务级!$A$9:$KF$30,233,FALSE) -> 108.55264 | BB12: =VLOOKUP(B12,拍照客户_业务级!$A$9:$KF$30,235,FALSE) -> -1.3626095 | BC12: =VLOOKUP(B12,拍照客户_业务级!$A$9:$KF$30,234,FALSE) -> 10.135374 | BD12: =VLOOKUP(B12,拍照客户_业务级!$A$9:$KF$30,123,FALSE) -> 98.118754 | BE12: =VLOOKUP(B12,拍照客户_业务级!$A$9:$KF$30,125,FALSE) -> 0.35273369 | BF12: =VLOOKUP(B12,拍照客户_业务级!$A$9:$KF$30,124,FALSE) -> -1.1101906 | BG12: =VLOOKUP(B12,拍照客户_业务级!$A$9:$KF$30,239,FALSE) -> 158.90719 | BH12: =VLOOKUP(B12,拍照客户_业务级!$A$9:$KF$30,241,FALSE) -> -10.614032 | BI12: =VLOOKUP(B12,拍照客户_业务级!$A$9:$KF$30,240,FALSE) -> 51.539741 | BJ12: =VLOOKUP(B12,拍照客户_业务级!$A$9:$KF$30,128,FALSE) -> 98.317506 | BK12: =VLOOKUP(B12,拍照客户_业务级!$A$9:$KF$30,130,FALSE) -> 1.7171849 | BL12: =VLOOKUP(B12,拍照客户_业务级!$A$9:$KF$30,129,FALSE) -> -0.59648751 | BM12: =VLOOKUP(B12,拍照客户_业务级!$A$9:$KF$30,245,FALSE) -> 116.18737 | BN12: =VLOOKUP(B12,拍照客户_业务级!$A$9:$KF$30,247,FALSE) -> -2.170395 | BO12: =VLOOKUP(B12,拍照客户_业务级!$A$9:$KF$30,246,FALSE) -> 34.104024
B13: 揭阳 | C13: =ROUND(VLOOKUP(B13,拍照客户_客户级!$A$2:$BX$27,28,FALSE)/10000,3) -> 803.687 | D13: =ROUND(VLOOKUP(B13,拍照客户_客户级!$A$2:$BX$27,29,FALSE)/10000,3) -> 1930.255 | E13: =ROUND(VLOOKUP(B13,拍照客户_客户级!$A$2:$BX$27,30,FALSE)/10000,3) -> -947.653 | F13: =ROUND(VLOOKUP(B13,拍照客户_客户级!$A$2:$BX$27,33,FALSE)/10000,3) -> -247.6 | G13: =ROUND(VLOOKUP(B13,拍照客户_客户级!$A$2:$BX$27,31,FALSE)/10000,3) -> 100.415 | H13: =ROUND(VLOOKUP(B13,拍照客户_客户级!$A$2:$BX$27,32,FALSE)/10000,3) -> -31.731 | I13: =VLOOKUP(B13,拍照客户_客户级!$A$2:$BX$27,13,FALSE) -> 93.515074 | J13: =VLOOKUP(B13,拍照客户_客户级!$A$2:$BX$27,15,FALSE) -> -0.93942591 | K13: =VLOOKUP(B13,拍照客户_客户级!$A$2:$BX$27,14,FALSE) -> -0.24778031 | L13: =VLOOKUP(B13,拍照客户_客户级!$A$2:$BX$27,34,FALSE) -> 107.97134 | M13: =VLOOKUP(B13,拍照客户_客户级!$A$2:$BX$27,36,FALSE) -> -2.0198312 | N13: =VLOOKUP(B13,拍照客户_客户级!$A$2:$BX$27,35,FALSE) -> -0.080806198 | O13: =VLOOKUP(B13,拍照客户_客户级!$A$2:$BX$27,49,FALSE) -> 5.0606814 | P13: =VLOOKUP(B13,拍照客户_客户级!$A$2:$BX$27,50,FALSE) -> 7.797133 | Q13: =VLOOKUP(B13,拍照客户_客户级!$A$2:$BX$27,51,FALSE) -> 18.449893 | R13: =VLOOKUP(B13,拍照客户_客户级!$A$2:$BX$27,52,FALSE) -> -10.82088 | S13: =VLOOKUP(B13,拍照客户_客户级!$A$2:$BX$27,55,FALSE) -> -2.7364516 | T13: =VLOOKUP(B13,拍照客户_业务级!$A$9:$KF$30,282,FALSE) -> 0.17831098 | U13: =VLOOKUP(B13,拍照客户_业务级!$A$9:$KF$30,284,FALSE) -> 5.386188 | V13: =VLOOKUP(B13,拍照客户_业务级!$A$9:$KF$30,285,FALSE) -> -3.520211 | W13: =VLOOKUP(B13,拍照客户_业务级!$A$9:$KF$30,251,FALSE) -> 102.36927 | X13: =VLOOKUP(B13,拍照客户_业务级!$A$9:$KF$30,253,FALSE) -> -0.37109357 | Y13: =VLOOKUP(B13,拍照客户_业务级!$A$9:$KF$30,252,FALSE) -> -1.397036 | Z13: =VLOOKUP(B13,拍照客户_业务级!$A$9:$KF$30,204,FALSE) -> 103.89813 | AA13: =VLOOKUP(B13,拍照客户_业务级!$A$9:$KF$30,206,FALSE) -> -0.43744029 | AB13: =VLOOKUP(B13,拍照客户_业务级!$A$9:$KF$30,205,FALSE) -> 2.9266537 | AC13: =VLOOKUP(B13,拍照客户_业务级!$A$9:$KF$30,78,FALSE) -> 96.456575 | AD13: =VLOOKUP(B13,拍照客户_业务级!$A$9:$KF$30,80,FALSE) -> -0.67239686 | AE13: =VLOOKUP(B13,拍照客户_业务级!$A$9:$KF$30,79,FALSE) -> 1.3023486 | AF13: =VLOOKUP(B13,拍照客户_业务级!$A$9:$KF$30,213,FALSE) -> 105.80175 | AG13: =VLOOKUP(B13,拍照客户_业务级!$A$9:$KF$30,215,FALSE) -> -0.32981016 | AH13: =VLOOKUP(B13,拍照客户_业务级!$A$9:$KF$30,214,FALSE) -> 3.3880451 | AI13: =VLOOKUP(B13,拍照客户_业务级!$A$9:$KF$30,94,FALSE) -> 93.213117 | AJ13: =VLOOKUP(B13,拍照客户_业务级!$A$9:$KF$30,96,FALSE) -> -2.3263044 | AK13: =VLOOKUP(B13,拍照客户_业务级!$A$9:$KF$30,95,FALSE) -> -3.2077077 | AL13: =VLOOKUP(B13,拍照客户_业务级!$A$9:$KF$30,221,FALSE) -> 96.877795 | AM13: =VLOOKUP(B13,拍照客户_业务级!$A$9:$KF$30,223,FALSE) -> 0.13005326 | AN13: =VLOOKUP(B13,拍照客户_业务级!$A$9:$KF$30,222,FALSE) -> -7.8972753 | AO13: =VLOOKUP(B13,拍照客户_业务级!$A$9:$KF$30,108,FALSE) -> 82.848716 | AP13: =VLOOKUP(B13,拍照客户_业务级!$A$9:$KF$30,110,FALSE) -> -5.5031228 | AQ13: =VLOOKUP(B13,拍照客户_业务级!$A$9:$KF$30,109,FALSE) -> -13.78267 | AR13: =VLOOKUP(B13,拍照客户_业务级!$A$9:$KF$30,227,FALSE) -> 92.475383 | AS13: =VLOOKUP(B13,拍照客户_业务级!$A$9:$KF$30,229,FALSE) -> -0.2540107 | AT13: =VLOOKUP(B13,拍照客户_业务级!$A$9:$KF$30,228,FALSE) -> -26.434087 | AU13: =VLOOKUP(B13,拍照客户_业务级!$A$9:$KF$30,118,FALSE) -> 94.705633 | AV13: =VLOOKUP(B13,拍照客户_业务级!$A$9:$KF$30,120,FALSE) -> -1.9039551 | AW13: =VLOOKUP(B13,拍照客户_业务级!$A$9:$KF$30,119,FALSE) -> -1.2828944 | AX13: =VLOOKUP(B13,拍照客户_业务级!$A$9:$KF$30,254,FALSE) -> 119.48822 | AY13: =VLOOKUP(B13,拍照客户_业务级!$A$9:$KF$30,256,FALSE) -> -4.6653237 | AZ13: =VLOOKUP(B13,拍照客户_业务级!$A$9:$KF$30,255,FALSE) -> 4.2246083 | BA13: =VLOOKUP(B13,拍照客户_业务级!$A$9:$KF$30,233,FALSE) -> 89.30823 | BB13: =VLOOKUP(B13,拍照客户_业务级!$A$9:$KF$30,235,FALSE) -> -1.4726298 | BC13: =VLOOKUP(B13,拍照客户_业务级!$A$9:$KF$30,234,FALSE) -> -17.519412 | BD13: =VLOOKUP(B13,拍照客户_业务级!$A$9:$KF$30,123,FALSE) -> 100.64103 | BE13: =VLOOKUP(B13,拍照客户_业务级!$A$9:$KF$30,125,FALSE) -> -0.18315018 | BF13: =VLOOKUP(B13,拍照客户_业务级!$A$9:$KF$30,124,FALSE) -> 1.4540338 | BG13: =VLOOKUP(B13,拍照客户_业务级!$A$9:$KF$30,239,FALSE) -> 136.0176 | BH13: =VLOOKUP(B13,拍照客户_业务级!$A$9:$KF$30,241,FALSE) -> -6.4139403 | BI13: =VLOOKUP(B13,拍照客户_业务级!$A$9:$KF$30,240,FALSE) -> 15.921693 | BJ13: =VLOOKUP(B13,拍照客户_业务级!$A$9:$KF$30,128,FALSE) -> 89.605995 | BK13: =VLOOKUP(B13,拍照客户_业务级!$A$9:$KF$30,130,FALSE) -> -4.5588591 | BL13: =VLOOKUP(B13,拍照客户_业务级!$A$9:$KF$30,129,FALSE) -> -14.601952 | BM13: =VLOOKUP(B13,拍照客户_业务级!$A$9:$KF$30,245,FALSE) -> 110.0776 | BN13: =VLOOKUP(B13,拍照客户_业务级!$A$9:$KF$30,247,FALSE) -> -5.1192647 | BO13: =VLOOKUP(B13,拍照客户_业务级!$A$9:$KF$30,246,FALSE) -> -10.13116
B14: 潮州 | C14: =ROUND(VLOOKUP(B14,拍照客户_客户级!$A$2:$BX$27,28,FALSE)/10000,3) -> -36.417 | D14: =ROUND(VLOOKUP(B14,拍照客户_客户级!$A$2:$BX$27,29,FALSE)/10000,3) -> 928.206 | E14: =ROUND(VLOOKUP(B14,拍照客户_客户级!$A$2:$BX$27,30,FALSE)/10000,3) -> -981.787 | F14: =ROUND(VLOOKUP(B14,拍照客户_客户级!$A$2:$BX$27,33,FALSE)/10000,3) -> -22.652 | G14: =ROUND(VLOOKUP(B14,拍照客户_客户级!$A$2:$BX$27,31,FALSE)/10000,3) -> 50.503 | H14: =ROUND(VLOOKUP(B14,拍照客户_客户级!$A$2:$BX$27,32,FALSE)/10000,3) -> -10.687 | I14: =VLOOKUP(B14,拍照客户_客户级!$A$2:$BX$27,13,FALSE) -> 96.41986 | J14: =VLOOKUP(B14,拍照客户_客户级!$A$2:$BX$27,15,FALSE) -> -0.64688541 | K14: =VLOOKUP(B14,拍照客户_客户级!$A$2:$BX$27,14,FALSE) -> 0.073380888 | L14: =VLOOKUP(B14,拍照客户_客户级!$A$2:$BX$27,34,FALSE) -> 99.390477 | M14: =VLOOKUP(B14,拍照客户_客户级!$A$2:$BX$27,36,FALSE) -> 0.22996719 | N14: =VLOOKUP(B14,拍照客户_客户级!$A$2:$BX$27,35,FALSE) -> -0.51317009 | O14: =VLOOKUP(B14,拍照客户_客户级!$A$2:$BX$27,49,FALSE) -> -1.460526 | P14: =VLOOKUP(B14,拍照客户_客户级!$A$2:$BX$27,50,FALSE) -> -1.0228883 | Q14: =VLOOKUP(B14,拍照客户_客户级!$A$2:$BX$27,51,FALSE) -> 15.298285 | R14: =VLOOKUP(B14,拍照客户_客户级!$A$2:$BX$27,52,FALSE) -> -16.535768 | S14: =VLOOKUP(B14,拍照客户_客户级!$A$2:$BX$27,55,FALSE) -> -0.4376377 | T14: =VLOOKUP(B14,拍照客户_业务级!$A$9:$KF$30,282,FALSE) -> -0.2624595 | U14: =VLOOKUP(B14,拍照客户_业务级!$A$9:$KF$30,284,FALSE) -> 0.64621676 | V14: =VLOOKUP(B14,拍照客户_业务级!$A$9:$KF$30,285,FALSE) -> 4.5418382 | W14: =VLOOKUP(B14,拍照客户_业务级!$A$9:$KF$30,251,FALSE) -> 100.96288 | X14: =VLOOKUP(B14,拍照客户_业务级!$A$9:$KF$30,253,FALSE) -> -0.78723678 | Y14: =VLOOKUP(B14,拍照客户_业务级!$A$9:$KF$30,252,FALSE) -> 2.2549749 | Z14: =VLOOKUP(B14,拍照客户_业务级!$A$9:$KF$30,204,FALSE) -> 103.00532 | AA14: =VLOOKUP(B14,拍照客户_业务级!$A$9:$KF$30,206,FALSE) -> -0.70858374 | AB14: =VLOOKUP(B14,拍照客户_业务级!$A$9:$KF$30,205,FALSE) -> 3.8781549 | AC14: =VLOOKUP(B14,拍照客户_业务级!$A$9:$KF$30,78,FALSE) -> 95.42144 | AD14: =VLOOKUP(B14,拍照客户_业务级!$A$9:$KF$30,80,FALSE) -> -0.55748377 | AE14: =VLOOKUP(B14,拍照客户_业务级!$A$9:$KF$30,79,FALSE) -> 2.5533549 | AF14: =VLOOKUP(B14,拍照客户_业务级!$A$9:$KF$30,213,FALSE) -> 99.813505 | AG14: =VLOOKUP(B14,拍照客户_业务级!$A$9:$KF$30,215,FALSE) -> -0.45591493 | AH14: =VLOOKUP(B14,拍照客户_业务级!$A$9:$KF$30,214,FALSE) -> 0.57025055 | AI14: =VLOOKUP(B14,拍照客户_业务级!$A$9:$KF$30,94,FALSE) -> 95.06422 | AJ14: =VLOOKUP(B14,拍照客户_业务级!$A$9:$KF$30,96,FALSE) -> -0.59633028 | AK14: =VLOOKUP(B14,拍照客户_业务级!$A$9:$KF$30,95,FALSE) -> -0.54868304 | AL14: =VLOOKUP(B14,拍照客户_业务级!$A$9:$KF$30,221,FALSE) -> 98.803142 | AM14: =VLOOKUP(B14,拍照客户_业务级!$A$9:$KF$30,223,FALSE) -> -0.70032787 | AN14: =VLOOKUP(B14,拍照客户_业务级!$A$9:$KF$30,222,FALSE) -> -4.6891332 | AO14: =VLOOKUP(B14,拍照客户_业务级!$A$9:$KF$30,108,FALSE) -> 83.372065 | AP14: =VLOOKUP(B14,拍照客户_业务级!$A$9:$KF$30,110,FALSE) -> -2.997035 | AQ14: =VLOOKUP(B14,拍照客户_业务级!$A$9:$KF$30,109,FALSE) -> -8.228389 | AR14: =VLOOKUP(B14,拍照客户_业务级!$A$9:$KF$30,227,FALSE) -> 94.250323 | AS14: =VLOOKUP(B14,拍照客户_业务级!$A$9:$KF$30,229,FALSE) -> -1.5499871 | AT14: =VLOOKUP(B14,拍照客户_业务级!$A$9:$KF$30,228,FALSE) -> -1.4501357 | AU14: =VLOOKUP(B14,拍照客户_业务级!$A$9:$KF$30,118,FALSE) -> 95.246261 | AV14: =VLOOKUP(B14,拍照客户_业务级!$A$9:$KF$30,120,FALSE) -> -1.2873612 | AW14: =VLOOKUP(B14,拍照客户_业务级!$A$9:$KF$30,119,FALSE) -> -1.9685497 | AX14: =VLOOKUP(B14,拍照客户_业务级!$A$9:$KF$30,254,FALSE) -> 102.32883 | AY14: =VLOOKUP(B14,拍照客户_业务级!$A$9:$KF$30,256,FALSE) -> -0.85015102 | AZ14: =VLOOKUP(B14,拍照客户_业务级!$A$9:$KF$30,255,FALSE) -> 15.794117 | BA14: =VLOOKUP(B14,拍照客户_业务级!$A$9:$KF$30,233,FALSE) -> 119.97688 | BB14: =VLOOKUP(B14,拍照客户_业务级!$A$9:$KF$30,235,FALSE) -> -0.33823909 | BC14: =VLOOKUP(B14,拍照客户_业务级!$A$9:$KF$30,234,FALSE) -> 20.393346 | BD14: =VLOOKUP(B14,拍照客户_业务级!$A$9:$KF$30,123,FALSE) -> 116.21112 | BE14: =VLOOKUP(B14,拍照客户_业务级!$A$9:$KF$30,125,FALSE) -> 1.0367578 | BF14: =VLOOKUP(B14,拍照客户_业务级!$A$9:$KF$30,124,FALSE) -> 0.93484856 | BG14: =VLOOKUP(B14,拍照客户_业务级!$A$9:$KF$30,239,FALSE) -> 95.391106 | BH14: =VLOOKUP(B14,拍照客户_业务级!$A$9:$KF$30,241,FALSE) -> -1.0513915 | BI14: =VLOOKUP(B14,拍照客户_业务级!$A$9:$KF$30,240,FALSE) -> 13.985707 | BJ14: =VLOOKUP(B14,拍照客户_业务级!$A$9:$KF$30,128,FALSE) -> 98.074727 | BK14: =VLOOKUP(B14,拍照客户_业务级!$A$9:$KF$30,130,FALSE) -> -9.9689998 | BL14: =VLOOKUP(B14,拍照客户_业务级!$A$9:$KF$30,129,FALSE) -> 2.1057996 | BM14: =VLOOKUP(B14,拍照客户_业务级!$A$9:$KF$30,245,FALSE) -> 87.501567 | BN14: =VLOOKUP(B14,拍照客户_业务级!$A$9:$KF$30,247,FALSE) -> 6.2553416 | BO14: =VLOOKUP(B14,拍照客户_业务级!$A$9:$KF$30,246,FALSE) -> -136.59055
B15: 汕尾 | C15: =ROUND(VLOOKUP(B15,拍照客户_客户级!$A$2:$BX$27,28,FALSE)/10000,3) -> -900.561 | D15: =ROUND(VLOOKUP(B15,拍照客户_客户级!$A$2:$BX$27,29,FALSE)/10000,3) -> 647.707 | E15: =ROUND(VLOOKUP(B15,拍照客户_客户级!$A$2:$BX$27,30,FALSE)/10000,3) -> -1477.73 | F15: =ROUND(VLOOKUP(B15,拍照客户_客户级!$A$2:$BX$27,33,FALSE)/10000,3) -> -102.717 | G15: =ROUND(VLOOKUP(B15,拍照客户_客户级!$A$2:$BX$27,31,FALSE)/10000,3) -> 52.863 | H15: =ROUND(VLOOKUP(B15,拍照客户_客户级!$A$2:$BX$27,32,FALSE)/10000,3) -> -20.685 | I15: =VLOOKUP(B15,拍照客户_客户级!$A$2:$BX$27,13,FALSE) -> 91.269188 | J15: =VLOOKUP(B15,拍照客户_客户级!$A$2:$BX$27,15,FALSE) -> -0.82102144 | K15: =VLOOKUP(B15,拍照客户_客户级!$A$2:$BX$27,14,FALSE) -> 0.73516514 | L15: =VLOOKUP(B15,拍照客户_客户级!$A$2:$BX$27,34,FALSE) -> 88.064871 | M15: =VLOOKUP(B15,拍照客户_客户级!$A$2:$BX$27,36,FALSE) -> -0.034081093 | N15: =VLOOKUP(B15,拍照客户_客户级!$A$2:$BX$27,35,FALSE) -> -9.1188254 | O15: =VLOOKUP(B15,拍照客户_客户级!$A$2:$BX$27,49,FALSE) -> -12.645289 | P15: =VLOOKUP(B15,拍照客户_客户级!$A$2:$BX$27,50,FALSE) -> -11.162409 | Q15: =VLOOKUP(B15,拍照客户_客户级!$A$2:$BX$27,51,FALSE) -> 8.4382629 | R15: =VLOOKUP(B15,拍照客户_客户级!$A$2:$BX$27,52,FALSE) -> -19.696237 | S15: =VLOOKUP(B15,拍照客户_客户级!$A$2:$BX$27,55,FALSE) -> -1.48288 | T15: =VLOOKUP(B15,拍照客户_业务级!$A$9:$KF$30,282,FALSE) -> -1.9124205 | U15: =VLOOKUP(B15,拍照客户_业务级!$A$9:$KF$30,284,FALSE) -> -8.8025442 | V15: =VLOOKUP(B15,拍照客户_业务级!$A$9:$KF$30,285,FALSE) -> -2.3285632 | W15: =VLOOKUP(B15,拍照客户_业务级!$A$9:$KF$30,251,FALSE) -> 97.554592 | X15: =VLOOKUP(B15,拍照客户_业务级!$A$9:$KF$30,253,FALSE) -> -0.69135663 | Y15: =VLOOKUP(B15,拍照客户_业务级!$A$9:$KF$30,252,FALSE) -> -5.5523519 | Z15: =VLOOKUP(B15,拍照客户_业务级!$A$9:$KF$30,204,FALSE) -> 98.096673 | AA15: =VLOOKUP(B15,拍照客户_业务级!$A$9:$KF$30,206,FALSE) -> -0.45874586 | AB15: =VLOOKUP(B15,拍照客户_业务级!$A$9:$KF$30,205,FALSE) -> -7.4746088 | AC15: =VLOOKUP(B15,拍照客户_业务级!$A$9:$KF$30,78,FALSE) -> 92.690367 | AD15: =VLOOKUP(B15,拍照客户_业务级!$A$9:$KF$30,80,FALSE) -> -0.81548833 | AE15: =VLOOKUP(B15,拍照客户_业务级!$A$9:$KF$30,79,FALSE) -> -0.66969378 | AF15: =VLOOKUP(B15,拍照客户_业务级!$A$9:$KF$30,213,FALSE) -> 102.06826 | AG15: =VLOOKUP(B15,拍照客户_业务级!$A$9:$KF$30,215,FALSE) -> -0.60252009 | AH15: =VLOOKUP(B15,拍照客户_业务级!$A$9:$KF$30,214,FALSE) -> -0.30009766 | AI15: =VLOOKUP(B15,拍照客户_业务级!$A$9:$KF$30,94,FALSE) -> 90.05534 | AJ15: =VLOOKUP(B15,拍照客户_业务级!$A$9:$KF$30,96,FALSE) -> -0.2404638 | AK15: =VLOOKUP(B15,拍照客户_业务级!$A$9:$KF$30,95,FALSE) -> -3.0619424 | AL15: =VLOOKUP(B15,拍照客户_业务级!$A$9:$KF$30,221,FALSE) -> 103.62191 | AM15: =VLOOKUP(B15,拍照客户_业务级!$A$9:$KF$30,223,FALSE) -> -0.089530215 | AN15: =VLOOKUP(B15,拍照客户_业务级!$A$9:$KF$30,222,FALSE) -> 0.82874186 | AO15: =VLOOKUP(B15,拍照客户_业务级!$A$9:$KF$30,108,FALSE) -> 87.898831 | AP15: =VLOOKUP(B15,拍照客户_业务级!$A$9:$KF$30,110,FALSE) -> -2.3175829 | AQ15: =VLOOKUP(B15,拍照客户_业务级!$A$9:$KF$30,109,FALSE) -> -5.2937136 | AR15: =VLOOKUP(B15,拍照客户_业务级!$A$9:$KF$30,227,FALSE) -> 89.652952 | AS15: =VLOOKUP(B15,拍照客户_业务级!$A$9:$KF$30,229,FALSE) -> -1.5836177 | AT15: =VLOOKUP(B15,拍照客户_业务级!$A$9:$KF$30,228,FALSE) -> -7.5735996 | AU15: =VLOOKUP(B15,拍照客户_业务级!$A$9:$KF$30,118,FALSE) -> 93.985664 | AV15: =VLOOKUP(B15,拍照客户_业务级!$A$9:$KF$30,120,FALSE) -> -0.94015669 | AW15: =VLOOKUP(B15,拍照客户_业务级!$A$9:$KF$30,119,FALSE) -> -1.0349401 | AX15: =VLOOKUP(B15,拍照客户_业务级!$A$9:$KF$30,254,FALSE) -> 79.502743 | AY15: =VLOOKUP(B15,拍照客户_业务级!$A$9:$KF$30,256,FALSE) -> 0.79331227 | AZ15: =VLOOKUP(B15,拍照客户_业务级!$A$9:$KF$30,255,FALSE) -> -12.273445 | BA15: =VLOOKUP(B15,拍照客户_业务级!$A$9:$KF$30,233,FALSE) -> 74.926431 | BB15: =VLOOKUP(B15,拍照客户_业务级!$A$9:$KF$30,235,FALSE) -> -0.3494261 | BC15: =VLOOKUP(B15,拍照客户_业务级!$A$9:$KF$30,234,FALSE) -> -16.131282 | BD15: =VLOOKUP(B15,拍照客户_业务级!$A$9:$KF$30,123,FALSE) -> 96.910112 | BE15: =VLOOKUP(B15,拍照客户_业务级!$A$9:$KF$30,125,FALSE) -> 0.42134831 | BF15: =VLOOKUP(B15,拍照客户_业务级!$A$9:$KF$30,124,FALSE) -> -42.327556 | BG15: =VLOOKUP(B15,拍照客户_业务级!$A$9:$KF$30,239,FALSE) -> 80.923709 | BH15: =VLOOKUP(B15,拍照客户_业务级!$A$9:$KF$30,241,FALSE) -> 1.148138 | BI15: =VLOOKUP(B15,拍照客户_业务级!$A$9:$KF$30,240,FALSE) -> -11.08769 | BJ15: =VLOOKUP(B15,拍照客户_业务级!$A$9:$KF$30,128,FALSE) -> 88.511771 | BK15: =VLOOKUP(B15,拍照客户_业务级!$A$9:$KF$30,130,FALSE) -> 0.15805673 | BL15: =VLOOKUP(B15,拍照客户_业务级!$A$9:$KF$30,129,FALSE) -> -12.188904 | BM15: =VLOOKUP(B15,拍照客户_业务级!$A$9:$KF$30,245,FALSE) -> 81.54358 | BN15: =VLOOKUP(B15,拍照客户_业务级!$A$9:$KF$30,247,FALSE) -> -0.54476392 | BO15: =VLOOKUP(B15,拍照客户_业务级!$A$9:$KF$30,246,FALSE) -> -10.388803
